Workbook
Name alloc_stu_grp: [1]stu_alloc!$B$2:$B$54
Name alloc_stu_grp: [2]stu_alloc!$B$2:$B$54
Name c_date: Report!$C$11
Name co_idx: [1]Report!$B$2
Name co_idx: [2]Report!$B$2
Name end_date: [1]Params!$B$7
Name end_date: [2]Params!$B$7
Name Ex_code: [2]Report!$B$4
Name Ex_code: [1]Report!$B$4
Name Ex_code: Report!$B$1
Name exch_code: [1]Params!$B$4
Name exch_code: [2]Params!$B$4
Name Master_mode: [1]hparams!#REF!
Name Master_mode: [2]hparams!#REF!
Name Setup_status: #REF!
Name st_id: #REF!
Name start_date: [1]Params!$B$8
Name start_date: [2]Params!$B$8
Name stu_grp: #REF!
Name stu_grp: #REF!
Name stu_idx: [1]hparams!$B$4
Name stu_idx: [2]hparams!$B$4
Name stu_key_id: [1]hparams!$B$3
Name stu_key_id: [2]hparams!$B$3

Sheet Instructions
A2: Individual Report - Excel Workbook Template | D2: Write your company name, Code and Sector here
A3: Student Number: | B3: 25062683 | D3: Company name | E3: Code | F3: Sector
B4: WORKBOOK TABS | D4: TELECOM PLUS PLC | E4: Communications | F4: TEP
A5: Instructions | B5: This page guides you through much of the preparation for the assignment.
A6: Co. Names | B6: List of all companies for which we have data and allocation to student. Please delete this sheet once you found your company.
A7: FTSE Data | B7: This has the daily cloing prices for a five year period, for the FTSE 350, FTSE-All shares, FTSE 100 Index for for comparison purposes, wherever applicable.
A8: Example Data | B8: This has the daily share prices for a five year period, for the FTSE 350 (FTSEAS) and for each company being allocated. (Example)
A9: Report | B9: In this worksheet you will build your summary of the company analysis (for use in your word report).
A10: Ret_data | B10: You will calculate the daily returns on this sheet.
A11: IS data | B11: This is where you will paste 3 years of Income Statements .
A12: SoFP data | B12: This is where you will paste 3 years of Statements of Financial Position (Balance Sheets)
A13: Custom Data | B13: Get 3 years of ratios for your assigned company and its competitor.
A14: Mkt_calc | B14: This is where you will put all of your market analysis calculations (risk and return in relation to share price).
A15: Fin_Calc | B15: This is where you will put all of your financial analysis calculations (based on the data in the financial statements) and create relevant charts or tables .
B17: INSTRUCTIONS
A18: 1 | B18: In this tab input your student number.
A19: 2 | B19: In tab 'Report' for the company you have been allocated, insert the company code (that the exchange uses) the official company name, and the sector in which it operates.
A20: 3 | B20: In tab 'Ret_data' calculate the daily returns (%) from the historical daily prices (found in the 'Data' tab) for your company the FTSE All-Shares or FTSE350 and/or competitor. Time period is 01/01/2022 to 31/12/2024 (3 years)
A21: 4 | B21: Extract the Income statement (IS) data and Statements of financial position (SoFP) data for each year ending 2022-2025 (3 years of data). Paste the data into the tabs 'IS data' and 'SoFP data' respectively.
A22: 5 | B22: Extract the various ratios for your company and a competitor for the same time period. Paste the data into the 'Custom data' tab and analyse the data creating useful charts/tables.
A23: 6 | B23: In tab 'Mkt_calc' calculate; the daily volatility and average returns, the annual returns and the volatility in each year. Then calculate the overall returns for the whole five years. In this tab you should include the Beta and PE ratio (collected from Yahoo finance ). You will need this for section 3 of your word report ' Market report'.
A24: 7 | B24: In tab 'Fin_calc' perform the analysis - ratio analysis over time and in comparison . Create the charts and tables in this tab. You will need this for section 2 of your word report ' Financial report'.
A25: 8 | B25: In tab 'Report' put all charts and tables that you will be utilising in your word report, these will be duplicates of the charts and tables in 'Fin_calc' and 'Mkt_calc'. Make sure that you number them so that you can cross reference to your report.
A26: 9 | B26: Tidy up the workbook and make it presentable/professional.
A28: REMEMBER: | B28: Regularly save copies of the workbook adding a version number on each save.
B29: Look up the company on FAME, Hargreaves Lansdown and Yahoo finance, to find information about the company and the sector it operates in.

Sheet Co. Names
A1: Company name | B1: BvD sector | C1: Ticker symbol | E1: Students Allocation
A2: LEGAL & GENERAL GROUP PLC | B2: Banking, Insurance & Financial Services | C2: LGEN | E2: Phan Hoàng | F2: An | J2: Once you identified your company please delete this sheet
A3: ADMIRAL GROUP PLC | B3: Banking, Insurance & Financial Services | C3: ADM | E3: Trương Bùi Thành | F3: An
A4: INVESTEC PLC | B4: Banking, Insurance & Financial Services | C4: INVP | E4: Lê Nguyễn Vân | F4: Anh
A5: CMC MARKETS PLC | B5: Banking, Insurance & Financial Services | C5: CMCX | E5: Nguyễn Phương | F5: Anh
A6: GENUS PLC | B6: Biotechnology and Life Sciences | C6: GNS | E6: Trần Duy | F6: Bảo
A7: OXFORD NANOPORE TECHNOLOGIES PLC | B7: Biotechnology and Life Sciences | C7: ONT | E7: Nguyễn Thanh | F7: Bình
A8: CURRYS PLC | B8: Business Services | C8: CURY | E8: Đậu Minh | F8: Châu
A9: EASYJET PLC | B9: Business Services | C9: EZJ | E9: Hoàng Đức | F9: Cường
A10: MITIE GROUP PLC | B10: Business Services | C10: MTO | E10: Trần Minh | F10: Đăng
A11: ITV PLC | B11: Business Services | C11: ITV | E11: Lê Ngân | F11: Hà
A12: SEVERN TRENT PLC | B12: Business Services | C12: SVT | E12: Tăng Thu | F12: Hằng
A13: VODAFONE GROUP PUBLIC LIMITED COMPANY | B13: Communications | C13: VOD | E13: Nguyễn Xuân | F13: Hậu
A14: BT GROUP PLC | B14: Communications | C14: BT.A | E14: Đỗ Minh | F14: Hoàng
... A36: PRIMARY HEALTH PROPERTIES PLC | B36: Property Services | C36: PHP | E36: Nguyễn Thị Hà | F36: Vy
A37: WATCHES OF SWITZERLAND GROUP PLC | B37: Retail | C37: WOSG
A38: EMPIRIC STUDENT PROPERTY PLC | B38: Property Services | C38: ESP
A39: TRAVIS PERKINS PLC | B39: Retail | C39: TPK
A40: THG PLC | B40: Retail | C40: THG
A41: WATCHES OF SWITZERLAND GROUP PLC | B41: Retail | C41: WOSG
A42: WICKES GROUP PLC | B42: Retail | C42: WIX
A43: BAE SYSTEMS PLC | B43: Transport Manufacturing | C43: BA.
A44: CARNIVAL PLC | B44: Transport, Freight & Storage | C44: CCL
A45: FIRSTGROUP PLC | B45: Transport, Freight & Storage | C45: FGP
A46: WIZZ AIR HOLDINGS PLC | B46: Transport, Freight & Storage | C46: WIZZ
A47: J D WETHERSPOON PLC | B47: Travel, Personal & Leisure | C47: JDW
A48: CONVATEC GROUP PLC | B48: Travel, Personal & Leisure | C48: CTEC
... A51: ME GROUP INTERNATIONAL PLC | B51: Travel, Personal & Leisure | C51: MEGP

Sheet FTSE Data
D1: Notes: Please use this data for comparison purposes, wherever applicable
A3: Last Price (£)
A5: Start Date | B5: 44562
A6: End Date | B6: 45657
B8: FTSE 100 Index | C8: FTSE-All Shares | D8: FTSE 350 Index
A9: Dates | B9: UKX Index | C9: ASX Index | D9: NMX Index
A10: 44564 | B10: 7384.54 | C10: 4208.02 | D10: 4228.67
A11: 44565 | B11: 7505.15 | C11: 4276.18 | D11: 4298.76
A12: 44566 | B12: 7516.87 | C12: 4277.51 | D12: 4300.35
A13: 44567 | B13: 7450.37 | C13: 4235.63 | D13: 4257.77
A14: 44568 | B14: 7485.28 | C14: 4249.43 | D14: 4272.27
A15: 44571 | B15: 7445.25 | C15: 4219.71 | D15: 4242.3
A16: 44572 | B16: 7491.37 | C16: 4241.88 | D16: 4264.93
A17: 44573 | B17: 7551.72 | C17: 4270.79 | D17: 4294.04
A18: 44574 | B18: 7563.85 | C18: 4273.23 | D18: 4296.99
A19: 44575 | B19: 7542.95 | C19: 4256.59 | D19: 4280.34
A20: 44578 | B20: 7611.23 | C20: 4292.58 | D20: 4316.64
A21: 44579 | B21: 7563.55 | C21: 4263.04 | D21: 4287.22
... A791: 45657 | B791: 8173.02 | C791: 4467.8 | D791: 4510.61

Sheet BT_GROUP_PLC
A1: Daily pricing series
A2: All figures have been adjusted based on the stock split ratio
B3: Open (£) | C3: High (£) | D3: Low (£) | E3: Close (£) | F3: Volume (shares) | G3: Shares outstanding | H3: Market cap (m £)
A4: 45989 | B4: 1.805 | C4: 1.8145 | D4: 1.786 | E4: 1.8095 | F4: 11775721 | G4: 9967572370 | H4: 18036.322
A5: 45988 | B5: 1.8155 | C5: 1.817 | D5: 1.7895 | E5: 1.806 | F5: 8611085 | G5: 9967572370 | H5: 18001.437
A6: 45987 | B6: 1.773 | C6: 1.8165 | D6: 1.771 | E6: 1.8135 | F6: 27528737 | G6: 9967572370 | H6: 18076.193
A7: 45986 | B7: 1.743 | C7: 1.787 | D7: 1.73 | E7: 1.7805 | F7: 15892389 | G7: 9967572370 | H7: 17747.263
A8: 45985 | B8: 1.7715 | C8: 1.7735 | D8: 1.7425 | E8: 1.7515 | F8: 19331302 | G8: 9967572370 | H8: 17458.202
A9: 45982 | B9: 1.753 | C9: 1.779 | D9: 1.748 | E9: 1.7665 | F9: 24907516 | G9: 9967572370 | H9: 17607.717
A10: 45981 | B10: 1.757 | C10: 1.7625 | D10: 1.744 | E10: 1.7625 | F10: 37631852 | G10: 9967572370 | H10: 17567.847
A11: 45980 | B11: 1.7735 | C11: 1.7785 | D11: 1.746 | E11: 1.746 | F11: 8820614 | G11: 9967572370 | H11: 17403.382
A12: 45979 | B12: 1.776 | C12: 1.7785 | D12: 1.76 | E12: 1.77 | F12: 32634124 | G12: 9967572370 | H12: 17642.603
A13: 45978 | B13: 1.772 | C13: 1.7885 | D13: 1.755 | E13: 1.787 | F13: 11001799 | G13: 9967572370 | H13: 17812.051
A14: 45975 | B14: 1.7915 | C14: 1.7915 | D14: 1.75 | E14: 1.765 | F14: 14282956 | G14: 9967572370 | H14: 17592.765
A15: 45974 | B15: 1.7825 | C15: 1.8065 | D15: 1.782 | E15: 1.7945 | F15: 7640854 | G15: 9967572370 | H15: 17886.809
... A6019: 37258 | B6019: 0 | C6019: 0 | D6019: 0 | E6019: 2.495 | F6019: 0 | G6019: 8670033956 | H6019: 21631.734

Sheet TELECOM_PLUS_PLC
A1: Daily pricing series
A2: All figures have been adjusted based on the stock split ratio
B3: Open (£) | C3: High (£) | D3: Low (£) | E3: Close (£) | F3: Volume (shares) | G3: Shares outstanding | H3: Market cap (m £)
A4: 45989 | B4: 16.040001 | C4: 16.08 | D4: 15.82 | E4: 15.82 | F4: 271630 | G4: 80081517 | H4: 1266.8896
A5: 45988 | B5: 16.48 | C5: 16.48 | D5: 15.94 | E5: 15.98 | F5: 132080 | G5: 80080823 | H5: 1279.6915
A6: 45987 | B6: 16.4 | C6: 16.5 | D6: 15.94 | E6: 16.16 | F6: 248721 | G6: 80080823 | H6: 1294.1061
A7: 45986 | B7: 17.48 | C7: 17.48 | D7: 16.42 | E7: 16.42 | F7: 319783 | G7: 80080823 | H7: 1314.9271
A8: 45985 | B8: 17.360001 | C8: 17.719999 | D8: 17.32 | E8: 17.42 | F8: 187097 | G8: 80080823 | H8: 1395.0079
A9: 45982 | B9: 17.24 | C9: 17.860001 | D9: 16.98 | E9: 17.700001 | F9: 428406 | G9: 80080823 | H9: 1417.4306
A10: 45981 | B10: 16.959999 | C10: 16.98 | D10: 16.76 | E10: 16.860001 | F10: 126734 | G10: 80080823 | H10: 1350.1627
A11: 45980 | B11: 16.780001 | C11: 17.040001 | D11: 16.74 | E11: 16.860001 | F11: 273994 | G11: 80080823 | H11: 1350.1627
A12: 45979 | B12: 16.9 | C12: 17.040001 | D12: 16.82 | E12: 16.98 | F12: 146673 | G12: 80080823 | H12: 1359.7723
A13: 45978 | B13: 16.82 | C13: 17.16 | D13: 16.82 | E13: 17.1 | F13: 140647 | G13: 80080823 | H13: 1369.3821
A14: 45975 | B14: 17.120001 | C14: 17.24 | D14: 16.719999 | E14: 17.120001 | F14: 101308 | G14: 80080823 | H14: 1370.9838
A15: 45974 | B15: 17.18 | C15: 17.18 | D15: 16.9 | E15: 16.9 | F15: 166516 | G15: 80080823 | H15: 1353.3659
... A5107: 38583 | B5107: 0 | C5107: 0 | D5107: 0 | E5107: 1.505 | F5107: 0 | G5107: 68140720 | H5107: 102.55178

Sheet My Data
B1: FTSEAS | C1: MOTR | D1: COMPETITOR
A2: Date | B2: Close | C2: Close | G2: This data shown here is just for illustration purpsoes, please replace with your allocated company, choosen competitor and choosen index
A3: 44564 | B3: 4228.67 | C3: 15.86 | D3: 1.6955
A4: 44565 | B4: 4298.76 | C4: 16.120001 | D4: 1.7265
A5: 44566 | B5: 4300.35 | C5: 15.84 | D5: 1.7575
A6: 44567 | B6: 4257.77 | C6: 15.38 | D6: 1.7555
A7: 44568 | B7: 4272.27 | C7: 15.42 | D7: 1.7605
A8: 44571 | B8: 4242.3 | C8: 15.34 | D8: 1.778
A9: 44572 | B9: 4264.93 | C9: 15.28 | D9: 1.7715
A10: 44573 | B10: 4294.04 | C10: 15.34 | D10: 1.7465
A11: 44574 | B11: 4296.99 | C11: 15.34 | D11: 1.7815
A12: 44575 | B12: 4280.34 | C12: 15.36 | D12: 1.796
A13: 44578 | B13: 4316.64 | C13: 15.12 | D13: 1.8105
A14: 44579 | B14: 4287.22 | C14: 15.08 | D14: 1.866
... A784: 45657 | B784: 4510.61 | C784: 17.18 | D784: 1.4405

Sheet Report
A1: Code | B1: MOTR
A2: Name | B2: Motorpoint Group PLC
A3: Sector
A6: Chart 1 | B6: Title
A20: Chart 2 | B20: Title
A27: Chart 4 | B27: Title
A34: Chart 5 | B34: Title
A41: Chart 6 | B41: Title
A48: Chart 7 | B48: Title
A55: Chart 8 | B55: Title
D85: Company | E85: Competitor
B86: Beta (3Y) | D86: 0.83 | E86: 0.81
B87: PE ratio (TTM) | C87: 2022 | D87: 29.87 | E87: 13.30
C88: 2023 | D88: 23.22 | E88: 8.01
C89: 2024 | D89: 18.77 | E89: 15.31

Sheet Ret_data
A1: Date | B1: MOTR | C1: COMPETITOR | D1: FTSEAS
A2: ='My Data'!A3 -> 44564 | B2: 0 | C2: 0 | D2: 0 | J2: Formula for Daily returns = Ln (Pt/Pt-1)
A3: ='My Data'!A4 -> 44565 | B3: =LN('My Data'!#REF!/'My Data'!#REF!) -> #REF! | C3: =LN('My Data'!#REF!/'My Data'!D3) -> #REF! | D3: =LN('My Data'!B3/'My Data'!B4) -> -0.016439086
A4: ='My Data'!A5 -> 44566 | B4: =LN('My Data'!#REF!/'My Data'!#REF!) -> #REF! | C4: =LN('My Data'!#REF!/'My Data'!#REF!) -> #REF! | D4: =LN('My Data'!B4/'My Data'!B5) -> -0.00036980572 | M4: natural log = (current price / previous price)
A5: ='My Data'!A6 -> 44567 | B5: =LN('My Data'!#REF!/'My Data'!#REF!) -> #REF! | C5: =LN('My Data'!#REF!/'My Data'!#REF!) -> #REF! | D5: =LN('My Data'!B5/'My Data'!B6) -> 0.0099508657
A6: ='My Data'!A7 -> 44568 | B6: =LN('My Data'!#REF!/'My Data'!#REF!) -> #REF! | C6: =LN('My Data'!#REF!/'My Data'!#REF!) -> #REF! | D6: =LN('My Data'!B6/'My Data'!B7) -> -0.0033997529
A7: ='My Data'!A8 -> 44571 | B7: =LN('My Data'!#REF!/'My Data'!#REF!) -> #REF! | C7: =LN('My Data'!#REF!/'My Data'!#REF!) -> #REF! | D7: =LN('My Data'!B7/'My Data'!B8) -> 0.0070397269
A8: ='My Data'!A9 -> 44572 | B8: =LN('My Data'!#REF!/'My Data'!#REF!) -> #REF! | C8: =LN('My Data'!#REF!/'My Data'!#REF!) -> #REF! | D8: =LN('My Data'!B8/'My Data'!B9) -> -0.0053201931
A9: ='My Data'!A10 -> 44573 | B9: =LN('My Data'!#REF!/'My Data'!#REF!) -> #REF! | C9: =LN('My Data'!#REF!/'My Data'!#REF!) -> #REF! | D9: =LN('My Data'!B9/'My Data'!B10) -> -0.0068022466
A10: ='My Data'!A11 -> 44574 | B10: =LN('My Data'!#REF!/'My Data'!#REF!) -> #REF! | C10: =LN('My Data'!#REF!/'My Data'!#REF!) -> #REF! | D10: =LN('My Data'!B10/'My Data'!B11) -> -0.00068676285
A11: ='My Data'!A12 -> 44575 | B11: =LN('My Data'!#REF!/'My Data'!#REF!) -> #REF! | C11: =LN('My Data'!#REF!/'My Data'!#REF!) -> #REF! | D11: =LN('My Data'!B11/'My Data'!B12) -> 0.0038823319
A12: ='My Data'!A13 -> 44578 | B12: =LN('My Data'!#REF!/'My Data'!#REF!) -> #REF! | C12: =LN('My Data'!#REF!/'My Data'!#REF!) -> #REF! | D12: =LN('My Data'!B12/'My Data'!B13) -> -0.0084448762
A13: ='My Data'!A14 -> 44579 | B13: =LN('My Data'!#REF!/'My Data'!#REF!) -> #REF! | C13: =LN('My Data'!#REF!/'My Data'!#REF!) -> #REF! | D13: =LN('My Data'!B13/'My Data'!B14) -> 0.0068388176
A14: ='My Data'!A15 -> 44580 | B14: =LN('My Data'!#REF!/'My Data'!#REF!) -> #REF! | C14: =LN('My Data'!#REF!/'My Data'!#REF!) -> #REF! | D14: =LN('My Data'!B14/'My Data'!B15) -> -0.0028904682
A15: ='My Data'!A16 -> 44581 | B15: =LN('My Data'!#REF!/'My Data'!#REF!) -> #REF! | C15: =LN('My Data'!#REF!/'My Data'!#REF!) -> #REF! | D15: =LN('My Data'!B15/'My Data'!B16) -> 7.2101826e-05
A16: ='My Data'!A17 -> 44582 | B16: =LN('My Data'!#REF!/'My Data'!#REF!) -> #REF! | C16: =LN('My Data'!#REF!/'My Data'!#REF!) -> #REF! | D16: =LN('My Data'!B16/'My Data'!B17) -> 0.013384297
... A783: ='My Data'!A784 -> 45657 | B783: =LN('My Data'!#REF!/'My Data'!#REF!) -> #REF! | C783: =LN('My Data'!#REF!/'My Data'!#REF!) -> #REF! | D783: =LN('My Data'!B783/'My Data'!B784) -> -0.0069388256
A784: ='My Data'!A785 -> 0
A785: ='My Data'!A786 -> 0
A786: ='My Data'!A787 -> 0
A787: ='My Data'!A788 -> 0
A788: ='My Data'!A789 -> 0
A789: ='My Data'!A790 -> 0
A790: ='My Data'!A791 -> 0
A791: ='My Data'!A792 -> 0
A792: ='My Data'!A793 -> 0
A793: ='My Data'!A794 -> 0
A794: ='My Data'!A795 -> 0
A795: ='My Data'!A796 -> 0
... A1263: ='My Data'!A1264 -> 0

Sheet FTSE All-Share Historical 
A1: Date | B1: Price
A2: 43832 | B2: 4285.97
A3: 43833 | B3: 4290.29
A4: 43836 | B4: 4260.71
A5: 43837 | B5: 4262.43
A6: 43838 | B6: 4256.79
A7: 43839 | B7: 4267.27
A8: 43840 | B8: 4259.91
A9: 43843 | B9: 4278.83
A10: 43844 | B10: 4282.37
A11: 43845 | B11: 4290.42
A12: 43846 | B12: 4275.36
A13: 43847 | B13: 4311.06
... A1262: 45656 | B1262: 4479.42

Sheet IS data
A1: PASTE 3 YEARS OF INCOME STATEMENT DATA HERE | I1: 45747 | J1: 45016 | K1: 44651 | L1: 44286
I2: th GBP | J2: th GBP | K2: th GBP | L2: th GBP
B3: 2024 | C3: 2023 | D3: 2022 | J3: 2024 | K3: 2023 | L3: 2022
B4: th GBP | C4: th GBP | D4: th GBP | J4: th GBP | K4: th GBP | L4: th GBP
A5: ∟ Turnover | B5: 2039131 | C5: 2475160 | D5: 967.433 | I5: ∟ Turnover | J5: 20797000 | K5: 20681000 | L5: 20850000
A6: ∟ National Turnover | B6: 2039131 | C6: 2475160 | D6: 967.433 | I6: ∟ National Turnover
A7: ∟ Overseas Turnover | I7: ∟ Overseas Turnover
A8: ∟ Cost of Sales | B8: -1683921 | C8: -2168964 | D8: -778.958 | I8: ∟ Cost of Sales
A9: ∟ Exceptional Items pre GP | I9: ∟ Exceptional Items pre GP
A10: ∟ Other Income pre GP | I10: ∟ Other Income pre GP
A11: ∟ Gross Profit | B11: 355.21 | C11: 306.196 | D11: 188.475 | I11: ∟ Gross Profit
A12: ∟ Administration Expenses | B12: -250.337 | C12: -221.458 | D12: -139.399 | I12: ∟ Administration Expenses | J12: -17634000 | K12: -17494000 | L12: -17673000
A13: ∟ Other Operating Income/Costs pre OP | B13: 1.377 | C13: 1.156 | D13: 1.844 | I13: ∟ Other Operating Income/Costs pre OP
A14: ∟ Exceptional Items pre OP | I14: ∟ Exceptional Items pre OP | J14: -949 | K14: -568 | L14: -292
A15: ∟ Operating Profit | B15: 106.25 | C15: 85.894 | D15: 50.92 | I15: ∟ Operating Profit | J15: 2214000 | K15: 2619000 | L15: 2885000
A16: ∟ Other Income | C16: 3.595 | D16: -1.139 | I16: ∟ Other Income | J16: -21 | K16: -59
A17: ∟ Total Other Income & Int. Received | B17: 3.482 | C17: 4.611 | D17: -1.003 | I17: ∟ Total Other Income & Int. Received | J17: 160 | K17: 4 | L17: 12
A18: ∟ Exceptional Items | I18: ∟ Exceptional Items
A19: ∟ Profit (Loss) on Sale of Operations | I19: ∟ Profit (Loss) on Sale of Operations
A20: ∟ Costs of Reorganisation | I20: ∟ Costs of Reorganisation
A21: ∟ Profit (Loss) on Disposal | I21: ∟ Profit (Loss) on Disposal
A22: ∟ Other Exceptional Items | I22: ∟ Other Exceptional Items
A23: ∟ Profit (Loss) before Interest paid | B23: 109.732 | C23: 90.505 | D23: 49.917 | I23: ∟ Profit (Loss) before Interest paid | J23: 2374000 | K23: 2623000 | L23: 2897000
A24: ∟ Interest Received | B24: 3.482 | C24: 1.016 | D24: 136 | I24: ∟ Interest Received | J24: 181 | K24: 63 | L24: 12
A25: ∟ Interest Paid | B25: -9.255 | C25: -5.051 | D25: -2.709 | I25: ∟ Interest Paid | J25: -1188000 | K25: -894 | L25: -934
A26: ∟ Paid to Bank | B26: -9.229 | C26: -5.032 | D26: -2.187 | I26: ∟ Paid to Bank
A27: ∟ Paid on Hire Purchase | I27: ∟ Paid on Hire Purchase
A28: ∟ Paid on Leasing | B28: -26 | C28: -17 | D28: -238 | I28: ∟ Paid on Leasing | J28: -134 | K28: -133 | L28: -133
A29: ∟ Other Interest Paid | C29: -2 | D29: -284 | I29: ∟ Other Interest Paid | J29: -1054000 | K29: -761 | L29: -801
A30: ∟ Net Interest | B30: -5.773 | C30: -4.035 | D30: -2.573 | I30: ∟ Net Interest | J30: -1007000 | K30: -831 | L30: -922
A31: ∟ Profit (Loss) before Tax | B31: 100.477 | C31: 85.454 | D31: 47.208 | I31: ∟ Profit (Loss) before Tax | J31: 1186000 | K31: 1729000 | L31: 1963000
A32: ∟ Taxation | B32: -29.44 | C32: -17.293 | D32: -12.205 | I32: ∟ Taxation | J32: -331 | K32: 176 | L32: -689
A33: ∟ Profit (Loss) after Tax | B33: 71.037 | C33: 68.161 | D33: 35.003 | I33: ∟ Profit (Loss) after Tax | J33: 855 | K33: 1905000 | L33: 1274000
A34: ∟ Extraordinary Items | I34: ∟ Extraordinary Items
A35: ∟ Minority Interests | C35: 265 | I35: ∟ Minority Interests
A36: ∟ Profit (Loss) for period [=Net income] | B36: 71.037 | C36: 68.426 | D36: 35.003 | I36: ∟ Profit (Loss) for period [=Net income] | J36: 855 | K36: 1905000 | L36: 1274000
A37: ∟ Dividends (Distributable profit) | B37: -64.982 | C37: -50.601 | D37: -44.787 | I37: ∟ Dividends (Distributable profit) | J37: -757 | K37: -751 | L37: -228
A38: ∟ Retained Profit(Loss) | B38: 6.055 | C38: 17.825 | D38: -9.784 | I38: ∟ Retained Profit(Loss) | J38: 98 | K38: 1154000 | L38: 1046000
A40: ∟ Depreciation | B40: 21.618 | C40: 3.968 | D40: 4.558 | I40: ∟ Depreciation | J40: 3000000 | K40: 3653000 | L40: 3357000
A41: ∟ Depreciation Owned Assets | B41: 21.358 | C41: 3.968 | D41: 4.558 | I41: ∟ Depreciation Owned Assets | J41: 2892000 | K41: 2878000 | L41: 2669000
...

Sheet SoFP data
A1: PASTE 3 YEARS OF STATEMENT OF FINANCIAL POSITION DATA HERE | J1: 45382 | K1: 45016 | L1: 44651
J2: th GBP | K2: th GBP | L2: th GBP
A3: Original documents | B3: 2024 | C3: 2023 | D3: 2022 | I3: Original documents | J3: 2024 | K3: 2023 | L3: 2022
B4: th GBP | C4: th GBP | D4: th GBP | J4: th GBP | K4: th GBP | L4: th GBP
A5: Fixed Assets | I5: Fixed Assets
A6: Tangible Assets | B6: 26.773 | C6: 34.087 | D6: 34.525 | I6: Tangible Assets | J6: 22562000 | K6: 25648000 | L6: 25028000
A7: ∟ Land & Buildings | B7: 23.39 | C7: 29.002 | D7: 30.216 | I7: ∟ Land & Buildings | J7: 20514000 | K7: 23252000 | L7: 22641000
A8: ∟ Freehold Land | I8: ∟ Freehold Land
A9: ∟ Leasehold Land | I9: ∟ Leasehold Land
A10: ∟ Fixtures & Fittings | I10: ∟ Fixtures & Fittings
A11: ∟ Plant & Vehicles | B11: 534 | C11: 549 | D11: 635 | I11: ∟ Plant & Vehicles | K11: 385 | L11: 369
A12: ∟ Plant | B12: 365 | C12: 375 | D12: 409 | I12: ∟ Plant
A13: ∟ Vehicles | B13: 169 | C13: 174 | D13: 226 | I13: ∟ Vehicles | K13: 385 | L13: 369
A14: ∟ Other Fixed Assets | B14: 2.849 | C14: 4.536 | D14: 3.674 | I14: ∟ Other Fixed Assets | J14: 2048000 | K14: 2011000 | L14: 2018000
A15: Intangible Assets | B15: 139.527 | C15: 146.233 | D15: 156.16 | I15: Intangible Assets | J15: 16562000 | K15: 13687000 | L15: 13809000
A16: Investments & other fixed assets | B16: 63.941 | C16: 47.529 | D16: 32.855 | I16: Investments & other fixed assets | J16: 3896000 | K16: 3960000 | L16: 2029000
A17: ∟ Fixed Assets | B17: 230.241 | C17: 227.849 | D17: 223.54 | I17: ∟ Fixed Assets | J17: 43020000 | K17: 43295000 | L17: 40866000
A19: Current Assets | I19: Current Assets
A20: Stock & W.I.P. | B20: 3.749 | C20: 5.698 | D20: 4.152 | I20: Stock & W.I.P. | J20: 409 | K20: 349 | L20: 610
A21: ∟ Stock | I21: ∟ Stock
A22: ∟ W.I.P. | I22: ∟ W.I.P.
A23: ∟ Finished Goods | I23: ∟ Finished Goods
A24: Trade Debtors | B24: 86.606 | C24: 50.241 | D24: 46.254 | I24: Trade Debtors | J24: 3309000 | K24: 2960000 | L24: 3229000
A25: Bank & Deposits | B25: 57.829 | C25: 193.804 | D25: 29.647 | I25: Bank & Deposits | J25: 414 | K25: 392 | L25: 777
A26: Other Current Assets | B26: 271.72 | C26: 316.02 | D26: 156.998 | I26: Other Current Assets | J26: 2058000 | K26: 2063000 | L26: 1442000
A27: ∟ Group Loans (asset) | I27: ∟ Group Loans (asset) | J27: 163 | K27: 268
A28: ∟ Directors Loans (asset) | I28: ∟ Directors Loans (asset)
A29: ∟ Other Debtors | B29: 39.625 | C29: 28.407 | D29: 18.004 | I29: ∟ Other Debtors | J29: 724 | K29: 665 | L29: 273
A30: ∟ Prepayments | B30: 231.994 | C30: 284.53 | D30: 138.994 | I30: ∟ Prepayments | J30: 748 | K30: 703 | L30: 673
A31: ∟ Deferred Taxation | B31: 101 | C31: 3.083 | I31: ∟ Deferred Taxation | J31: 423 | K31: 427 | L31: 496
A32: Investments & other current assets | B32: 1.246 | C32: 1.127 | D32: 5.194 | I32: Investments & other current assets | J32: 2529000 | K32: 3693000 | L32: 2850000
A33: ∟ Current Assets | B33: 421.15 | C33: 566.89 | D33: 242.245 | I33: ∟ Current Assets | J33: 8719000 | K33: 9457000 | L33: 8908000
A35: Current Liabilities | I35: Current Liabilities
A36: Trade Creditors | B36: -100.974 | C36: -38.83 | D36: -28.644 | I36: Trade Creditors | J36: -5025000 | K36: -4196000 | L36: -4143000
A37: Short Term Loans & Overdrafts | I37: Short Term Loans & Overdrafts | J37: -1395000 | K37: -2572000 | L37: -1668000
A38: ∟ Bank Overdrafts | I38: ∟ Bank Overdrafts
A39: ∟ Group Loans (short t.) | I39: ∟ Group Loans (short t.)
A40: ∟ Director Loans (short t.) | I40: ∟ Director Loans (short t.)
A41: ∟ Hire Purch. & Leas. (short t.) | I41: ∟ Hire Purch. & Leas. (short t.) | K41: -800 | L41: -795
A42: ∟ Hire Purchase (short t.) | I42: ∟ Hire Purchase (short t.)
...

Sheet Custom data
A1: PASTE 3 YEARS OF DATA FROM CHOOSEN DATA SOURCE WITH KEY RATIOS FOR OWN COMPANY AND COMPETITOR. ANALYSE AND CREATE CHARTS.
A3: Profitability Ratios: Profit margin (%) | E3: Efficiency Ratios: Net Assets Turnover (x) | I3: Gearing ratios: Gearing (%) | M3: Equity Ratios: | Q3: Liquidity ratios:
B4: Company | C4: Competitor/Industry Average | F4: Company | G4: Competitor/Industry Average | J4: Company | K4: Competitor/Industry Average | N4: Company | O4: Competitor/Industry Average | R4: Company | S4: Competitor/Industry Average
A5: 2022 | B5: 4.88 | C5: 9.41 | E5: 2022 | F5: 3.16 | G5: 0.51 | I5: 2022 | J5: 49.16 | K5: 177.17 | M5: 2022 | N5: 22.96 | O5: 12.83 | Q5: 2022 | R5: 1.52 | S5: 0.98
A6: 2023 | B6: 3.45 | C6: 8.36 | E6: 2023 | F6: 7.69 | G6: 0.49 | I6: 2023 | J6: 39.57 | K6: 209.58 | M6: 2023 | N6: 37.04 | O6: 11.91 | Q6: 2023 | R6: 1.2 | S6: 0.91
A7: 2024 | B7: 4.93 | C7: 5.7 | E7: 2024 | F7: 4.92 | G7: 0.5 | I7: 2024 | J7: 77.99 | K7: 246.03 | M7: 2024 | N7: 43.19 | O7: 9.47 | Q7: 2024 | R7: 1.77 | S7: 0.89

Sheet Mkt_calc
B1: Equity Return and Risk
C2: Company | D2: FTSEAS | E2: Competitor
B3: Average Daily Return | C3: =AVERAGE(Ret_data!B2:B783) -> #REF! | D3: =AVERAGE(Ret_data!D2:D783) -> -8.2538205e-05 | E3: =AVERAGE(Ret_data!C2:C783) -> #REF!
B4: Volatility (Standard deviation) | C4: =STDEV(Ret_data!B2:B783) -> #REF! | D4: =STDEV(Ret_data!D2:D783) -> 0.0079590321 | E4: =STDEV(Ret_data!C2:C783) -> #REF!
B5: 3 year return | C5: =C3*252*3 -> #REF! | D5: =D3*252*3 -> -0.062398883 | E5: =E3*252*3 -> #REF!
A6: Annual return | B6: 2022 | C6: =AVERAGE(Ret_data!B2:B261)*252 -> #REF! | D6: =AVERAGE(Ret_data!D2:D261)*252 -> 0.026697664 | E6: =AVERAGE(Ret_data!C2:C261)*252 -> #REF!
B7: 2023 | C7: =AVERAGE(Ret_data!B262:B521)*252 -> #REF! | D7: =AVERAGE(Ret_data!D262:D521)*252 -> -0.036859854 | E7: =AVERAGE(Ret_data!C262:C521)*252 -> #REF!
B8: 2024 | C8: =AVERAGE(Ret_data!B522:B783)*252 -> #REF! | D8: =AVERAGE(Ret_data!D522:D783)*252 -> -0.051996716 | E8: =AVERAGE(Ret_data!C522:C783)*252 -> #REF!
A9: Annual volatility | B9: 2022 | C9: =STDEV(Ret_data!B2:B261)*SQRT(252) -> #REF! | D9: =STDEV(Ret_data!D2:D261)*SQRT(252) -> 0.16267515 | E9: =STDEV(Ret_data!C2:C261)*SQRT(252) -> #REF!
B10: 2023 | C10: =STDEV(Ret_data!B262:B521)*SQRT(252) -> #REF! | D10: =STDEV(Ret_data!D262:D521)*SQRT(252) -> 0.11455636 | E10: =STDEV(Ret_data!C262:C521)*SQRT(252) -> #REF!
B11: 2024 | C11: =STDEV(Ret_data!B522:B783)*SQRT(252) -> #REF! | D11: =STDEV(Ret_data!D522:D783)*SQRT(252) -> 0.092035658 | E11: =STDEV(Ret_data!C522:C783)*SQRT(252) -> #REF!
A13: FROM FAME
D14: Company | E14: Competitor
B15: Beta (3Y) | D15: 0.83 | E15: 0.81
B16: PE ratio (TTM) | C16: 2022 | D16: 29.87 | E16: 13.30
C17: 2023 | D17: 23.22 | E17: 8.01
C18: 2024 | D18: 18.77 | E18: 15.31

Sheet Fin_calc
A1: THIS IS YOUR SPACE TO CALCULATE THE RATIOS, PERFORM FINANCIAL ANALYSIS ON THE INCOME STATEMENT AND THE SoFP, AND CREATE THE CHARTS/TABLES FOR THE REPORT PAGE.
A3: Profitability Ratios: Profit margin (%) | E3: Efficiency Ratios: Net Assets Turnover (x) | I3: Gearing ratios: Gearing (%) | M3: Equity Ratios: Return on Shareholder Funds (%) | Q3: Liquidity ratios: Current Ratio
B4: Company | C4: Competitor/Industry Average | F4: Company | G4: Competitor/Industry Average | J4: Company | K4: Competitor/Industry Average | N4: Company | O4: Competitor/Industry Average | R4: Company | S4: Competitor/Industry Average
A5: 2022 | B5: =('IS data'!D15/'IS data'!D5) -> 0.052634136 | C5: =('IS data'!L15/'IS data'!L5) -> 0.1383693 | E5: 2022 | F5: =('IS data'!D5/'SoFP data'!D57) -> 3.1550295 | G5: =('IS data'!L5/'SoFP data'!L57) -> 0.51193282 | I5: 2022 | J5: =ABS('SoFP data'!D75) / (ABS('SoFP data'!D75) + ABS('SoFP data'!D90)) -> 0.32957747 | K5: =ABS('SoFP data'!L75) / (ABS('SoFP data'!L75) + ABS('SoFP data'!L90)) -> 0.62443528 | M5: 2022 | N5: =('IS data'!D31/'SoFP data'!D90) -> 0.22964105 | O5: =('IS data'!L31/'SoFP data'!L90) -> 0.12833421 | Q5: 2022 | R5: ='SoFP data'!D33/ABS('SoFP data'!D51) -> 1.5220888 | S5: ='SoFP data'!L33/ABS('SoFP data'!L51) -> 0.98474464
A6: 2023 | B6: =('IS data'!C15/'IS data'!C5) -> 3.4702403e-05 | C6: =('IS data'!K15/'IS data'!K5) -> 0.12663798 | E6: 2023 | F6: =('IS data'!C5 / 'SoFP data'!C57) -> 7687.0949 | G6: =('IS data'!K5/'SoFP data'!K57) -> 0.48822002 | I6: 2023 | J6: =ABS('SoFP data'!C75) / (ABS('SoFP data'!C75) + ABS('SoFP data'!C90)) -> 0.28349105 | K6: =ABS('SoFP data'!K75) / (ABS('SoFP data'!K75) + ABS('SoFP data'!K90)) -> 0.65736544 | M6: 2023 | N6: =('IS data'!C31/'SoFP data'!C90) -> 0.37039895 | O6: =('IS data'!K31/'SoFP data'!K90) -> 0.11912636 | Q6: 2023 | R6: ='SoFP data'!C33/ABS('SoFP data'!C51) -> 1.1991327 | S6: ='SoFP data'!K33/ABS('SoFP data'!K51) -> 0.91002694
A7: 2024 | B7: =('IS data'!B15/'IS data'!B5) -> 5.2105529e-05 | C7: =('IS data'!J15/'IS data'!J5) -> 0.10645766 | E7: 2024 | F7: =('IS data'!B5 / 'SoFP data'!B57) -> 4924.6402 | G7: =('IS data'!J5/'SoFP data'!J57) -> 0.49609981 | I7: 2024 | J7: =ABS('SoFP data'!B75) / (ABS('SoFP data'!B75) + ABS('SoFP data'!B90)) -> 0.43818029 | K7: =ABS('SoFP data'!J75) / (ABS('SoFP data'!J75) + ABS('SoFP data'!J90)) -> 0.70139071 | M7: 2024 | N7: =('IS data'!B31/'SoFP data'!B90) -> 0.43191578 | O7: =('IS data'!J31/'SoFP data'!J90) -> 0.094743569 | Q7: 2024 | R7: ='SoFP data'!B33/ABS('SoFP data'!B51) -> 1.7745782 | S7: ='SoFP data'!J33/ABS('SoFP data'!J51) -> 0.88806274

Sheet All stock Data
C1: XLON:FSTA | D1: XLON:GFRD | E1: XLON:HFD | F1: XLON:BOOT | G1: XLON:HSW | H1: XLON:KMR | I1: XLON:MARS | J1: XLON:MOTR | K1: XLON:NXR | L1: XLON:OTB | M1: XLON:OXB | N1: XLON:MAB | O1: XLON:YNGA | P1: XLON:MGNS | Q1: XLON:KIE | R1: XLON:COST | S1: XLON:VTU | T1: XLON:VCP | U1: XLON:JHD | V1: XLON:WJG | W1: XLON:RIO | X1: XLON:AAL | Y1: XLON:CAML | Z1: XLON:JDW | AA1: XLON:CKN | AB1: XLON:BAB | AC1: XLON:OCN | AD1: XLON:FERG | AE1: XLON:JET2 | AF1: XLON:HIK | AG1: XLON:SNG
A2: Date | C2: Close | D2: Close | E2: Close | F2: Close | G2: Close | H2: Close | I2: Close | J2: Close | K2: Close | L2: Close | M2: Close | N2: Close | O2: Close | P2: Close | Q2: Close | R2: Close | S2: Close | T2: Close | U2: Close | V2: Close | W2: Close | X2: Close | Y2: Close | Z2: Close | AA2: Close | AB2: Close | AC2: Close | AD2: Close | AE2: Close | AF2: Close | AG2: Close
A3: 43832 | B3: =VLOOKUP(A3,'FTSE All-Share Historical '!A:B,2,FALSE) -> 4285.97 | C3: 960 | D3: 886 | E3: 170.3 | F3: 330 | G3: 128.8 | H3: 239 | I3: 129.6 | J3: 289 | K3: 278 | L3: 489.2 | M3: 673 | N3: 456.5 | O3: 1627.5 | P3: 1620 | Q3: 94.75 | R3: 165 | S3: 38.3 | T3: 432.5 | U3: 270.5 | V3: 244 | W3: 4526.5 | X3: 2193.1259 | Y3: 223 | Z3: 1678 | AA3: 3030 | AB3: 631 | AC3: 990 | AD3: 6978 | AE3: 1723 | AF3: 1985 | AG3: 4.2439
A4: 43833 | B4: =VLOOKUP(A4,'FTSE All-Share Historical '!A:B,2,FALSE) -> 4290.29 | C4: 940 | D4: 165.86 | E4: 167.8 | F4: 322 | G4: 128.8 | H4: 239 | I4: 128.2 | J4: 294 | K4: 276 | L4: 490 | M4: 670 | N4: 456.5 | O4: 1650 | P4: 1610 | Q4: 91.7 | R4: 166.6 | S4: 37 | T4: 434 | U4: 266 | V4: 246 | W4: 4504 | X4: 2177.6884 | Y4: 221 | Z4: 1676 | AA4: 2995 | AB4: 613 | AC4: 990 | AD4: 7006 | AE4: 1675 | AF4: 1986 | AG4: 4.6051
A5: 43836 | B5: =VLOOKUP(A5,'FTSE All-Share Historical '!A:B,2,FALSE) -> 4260.71 | C5: 950 | D5: 163 | E5: 162.3 | F5: 330 | G5: 127.8 | H5: 241 | I5: 125.7 | J5: 290 | K5: 280 | L5: 478 | M5: 675 | N5: 443 | O5: 1660 | P5: 1580 | Q5: 90.5 | R5: 164.2 | S5: 36.4 | T5: 432.5 | U5: 269 | V5: 244 | W5: 4430 | X5: 2136.3557 | Y5: 216 | Z5: 1644 | AA5: 2935 | AB5: 628.4 | AC5: 995 | AD5: 6906 | AE5: 1674 | AF5: 1912 | AG5: 4.4245
A6: 43837 | B6: =VLOOKUP(A6,'FTSE All-Share Historical '!A:B,2,FALSE) -> 4262.43 | C6: 966 | D6: 136.42 | E6: 159.9 | F6: 330 | G6: 130.4 | H6: 245 | I6: 125 | J6: 288 | K6: 280 | L6: 481.8 | M6: 670 | N6: 439.5 | O6: 1637.5 | P6: 1616 | Q6: 89.5 | R6: 167 | S6: 37.1 | T6: 435 | U6: 273 | V6: 244 | W6: 4440 | X6: 2151.2952 | Y6: 215.5 | Z6: 1626 | AA6: 2955 | AB6: 646.6 | AC6: 995 | AD6: 6948 | AE6: 1670 | AF6: 1882.5 | AG6: 4.3703
A7: 43838 | B7: =VLOOKUP(A7,'FTSE All-Share Historical '!A:B,2,FALSE) -> 4256.79 | C7: 958 | D7: 144.08 | E7: 158 | F7: 320 | G7: 130 | H7: 240.5 | I7: 122.7 | J7: 290 | K7: 280 | L7: 468.4 | M7: 665 | N7: 421.5 | O7: 1605 | P7: 1640 | Q7: 87.05 | R7: 166.6 | S7: 36.9 | T7: 438 | U7: 268 | V7: 242.5 | W7: 4500 | X7: 2144.3234 | Y7: 217 | Z7: 1625 | AA7: 2945 | AB7: 641 | AC7: 990 | AD7: 6980 | AE7: 1675 | AF7: 1874.5 | AG7: 4.6954
A8: 43839 | B8: =VLOOKUP(A8,'FTSE All-Share Historical '!A:B,2,FALSE) -> 4267.27 | C8: 956 | D8: 151.5 | E8: 154.1 | F8: 315 | G8: 133 | H8: 235 | I8: 123.1 | J8: 278 | K8: 283.5 | L8: 461 | M8: 675 | N8: 433 | O8: 1650 | P8: 1652 | Q8: 83.1 | R8: 162.6 | S8: 37.35 | T8: 437.5 | U8: 270 | V8: 242 | W8: 4451 | X8: 2135.3597 | Y8: 224.5 | Z8: 1622 | AA8: 2925 | AB8: 643.2 | AC8: 980 | AD8: 7146 | AE8: 1705 | AF8: 1902 | AG8: 4.6051
A9: 43840 | B9: =VLOOKUP(A9,'FTSE All-Share Historical '!A:B,2,FALSE) -> 4259.91 | C9: 962 | D9: 158.4 | E9: 142 | F9: 313 | G9: 136 | H9: 233 | I9: 121.2 | J9: 277 | K9: 283 | L9: 461 | M9: 690 | N9: 433 | O9: 1630 | P9: 1664 | Q9: 82.5 | R9: 166 | S9: 37.25 | T9: 432 | U9: 270 | V9: 242 | W9: 4488 | X9: 2156.2751 | Y9: 222 | Z9: 1605 | AA9: 2925 | AB9: 636 | AC9: 980 | AD9: 7078 | AE9: 1817 | AF9: 1906.5 | AG9: 4.4606
A10: 43843 | B10: =VLOOKUP(A10,'FTSE All-Share Historical '!A:B,2,FALSE) -> 4278.83 | C10: 978 | D10: 157.7 | E10: 146 | F10: 313 | G10: 144 | H10: 240 | I10: 118.4 | J10: 286 | K10: 289 | L10: 464 | M10: 700 | N10: 420.5 | O10: 1622.5 | P10: 1648 | Q10: 83.8 | R10: 168.6 | S10: 37 | T10: 440 | U10: 278 | V10: 241.5 | W10: 4555 | X10: 2176.6924 | Y10: 228 | Z10: 1600 | AA10: 2925 | AB10: 638.4 | AC10: 975 | AD10: 7166 | AE10: 1806 | AF10: 1928 | AG10: 4.4606
A11: 43844 | B11: =VLOOKUP(A11,'FTSE All-Share Historical '!A:B,2,FALSE) -> 4282.37 | C11: 961 | D11: 158.26 | E11: 146 | F11: 325 | G11: 143.6 | H11: 235 | I11: 120.8 | J11: 295 | K11: 290 | L11: 450.2 | M11: 695 | N11: 425 | O11: 1620 | P11: 1646 | Q11: 81.95 | R11: 170.2 | S11: 36.7 | T11: 440 | U11: 275 | V11: 248 | W11: 4545 | X11: 2163.7448 | Y11: 230 | Z11: 1599 | AA11: 2905 | AB11: 632.6 | AC11: 980 | AD11: 7216 | AE11: 1803 | AF11: 1944.5 | AG11: 4.9121
A12: 43845 | B12: =VLOOKUP(A12,'FTSE All-Share Historical '!A:B,2,FALSE) -> 4290.42 | C12: 970 | D12: 151.86 | E12: 145.5 | F12: 335 | G12: 149.8 | H12: 236 | I12: 122.3 | J12: 294 | K12: 285 | L12: 457 | M12: 700 | N12: 417 | O12: 1610 | P12: 1680 | Q12: 77.5 | R12: 165.2 | S12: 36.1 | T12: 437.5 | U12: 281 | V12: 248.5 | W12: 4523 | X12: 2152.7892 | Y12: 228 | Z12: 1600 | AA12: 2950 | AB12: 618.8 | AC12: 1000 | AD12: 7176 | AE12: 1820 | AF12: 1975 | AG12: 5.0927
A13: 43846 | B13: =VLOOKUP(A13,'FTSE All-Share Historical '!A:B,2,FALSE) -> 4275.36 | C13: 970 | D13: 145.98 | E13: 153.5 | F13: 328 | G13: 149.4 | H13: 235 | I13: 123.4 | J13: 300 | K13: 281 | L13: 455.8 | M13: 671 | N13: 412.5 | O13: 1630 | P13: 1716 | Q13: 78 | R13: 170.4 | S13: 36.8 | T13: 437.5 | U13: 281 | V13: 250 | W13: 4526.5 | X13: 2166.7327 | Y13: 220.5 | Z13: 1600 | AA13: 3010 | AB13: 609.8 | AC13: 1025 | AD13: 7170 | AE13: 1777 | AF13: 1910.5 | AG13: 5.9596
A14: 43847 | B14: =VLOOKUP(A14,'FTSE All-Share Historical '!A:B,2,FALSE) -> 4311.06 | C14: 970 | D14: 142.88 | E14: 152 | F14: 342 | G14: 153.2 | H14: 237 | I14: 121.3 | J14: 304 | K14: 290 | L14: 437 | M14: 679 | N14: 411 | O14: 1625 | P14: 1696 | Q14: 78.4 | R14: 175.6 | S14: 38.15 | T14: 440 | U14: 279 | V14: 255 | W14: 4651 | X14: 2236.4506 | Y14: 224.5 | Z14: 1623 | AA14: 3075 | AB14: 620.2 | AC14: 1025 | AD14: 7176 | AE14: 1792 | AF14: 1955.5 | AG14: 5.779
... A357: 44343 | B357: =VLOOKUP(A357,'FTSE All-Share Historical '!A:B,2,FALSE) -> 4030.8 | C357: 884 | D357: 129.3 | E357: 385.2 | F357: 283 | G357: 100.8 | H357: 441 | I357: 93.7 | J357: 280 | K357: 297 | L357: 419.5 | M357: 1152 | N357: 316.2 | O357: 1630 | P357: 2275 | Q357: 116.6 | R357: 58.6 | S357: 43 | T357: 1010 | U357: 245 | V357: 238.5 | W357: 6074 | X357: 3124.8559 | Y357: 274 | Z357: 1354 | AA357: 3075 | AB357: 305 | AC357: 1065 | AD357: 9624 | AE357: 1345.5 | AF357: 2454 | AG357: 106.0439
A358: 44344 | B358: =VLOOKUP(A358,'FTSE All-Share Historical '!A:B,2,FALSE) -> 4032.98 | C358: 842 | D358: 125.8 | E358: 381.4 | F358: #N/A | G358: 97.2 | H358: 431 | I358: 91.35 | J358: 268 | K358: 305 | L358: 408 | M358: 1140 | N358: 305 | O358: 1610 | P358: 2235 | Q358: 115 | R358: 58.1 | S358: 43.5 | T358: 1005 | U358: 250 | V358: 225 | W358: 6064 | X358: 3122.366 | Y358: 272 | Z358: 1317 | AA358: 3080 | AB358: 299.1 | AC358: 1080 | AD358: 9584 | AE358: 1350 | AF358: 2444 | AG358: 117.7463
A359: 44348 | B359: =VLOOKUP(A359,'FTSE All-Share Historical '!A:B,2,FALSE) -> 4066.34 | C359: 924 | D359: 125.4 | E359: 386.6 | F359: 285 | G359: 97.9 | H359: 449 | I359: 94.7 | J359: 287 | K359: 297 | L359: 421.5 | M359: 1132 | N359: 310.8 | O359: 1600 | P359: 2270 | Q359: 115.2 | R359: 58.8 | S359: 43.9 | T359: 1025 | U359: 249.5 | V359: 226 | W359: 6305 | X359: 3248.3562 | Y359: 277.5 | Z359: 1351 | AA359: 3110 | AB359: 298.7 | AC359: 1070 | AD359: 9632 | AE359: 1360 | AF359: 2435 | AG359: 126.9204
A360: 44349 | B360: =VLOOKUP(A360,'FTSE All-Share Historical '!A:B,2,FALSE) -> 4081.16 | C360: 900 | D360: 126 | E360: 380.8 | F360: 280 | G360: 98 | H360: 441 | I360: 94.7 | J360: 276 | K360: 309 | L360: 427.5 | M360: 1120 | N360: 312.6 | O360: 1590 | P360: 2280 | Q360: 114.8 | R360: 58.6 | S360: 44.7 | T360: 1005 | U360: 248.5 | V360: 222 | W360: 6305 | X360: 3282.2191 | Y360: 284.5 | Z360: 1338 | AA360: 3105 | AB360: 306.9 | AC360: 1070 | AD360: 9660 | AE360: 1357.5 | AF360: 2423 | AG360: 122.8029
A361: 44350 | B361: =VLOOKUP(A361,'FTSE All-Share Historical '!A:B,2,FALSE) -> 4056.42 | C361: 854 | D361: 127.9 | E361: 376.4 | F361: 277 | G361: 96 | H361: 450 | I361: 93 | J361: 279 | K361: 302.5 | L361: 428 | M361: 1128 | N361: 307.2 | O361: 1590 | P361: 2250 | Q361: 113 | R361: 57.1 | S361: 46.3 | T361: 1005 | U361: 251 | V361: 224.5 | W361: 6172 | X361: 3188.1 | Y361: 274.5 | Z361: 1315 | AA361: 3115 | AB361: 305.4 | AC361: 1070 | AD361: 9802 | AE361: 1293 | AF361: 2403 | AG361: 121.1414
A362: 44351 | B362: =VLOOKUP(A362,'FTSE All-Share Historical '!A:B,2,FALSE) -> 4059.61 | C362: 882 | D362: 128.9 | E362: 379 | F362: 280 | G362: 97 | H362: 441 | I362: 94.35 | J362: 281 | K362: 298 | L362: 418 | M362: 1140 | N362: 311.6 | O362: 1590 | P362: 2230 | Q362: 112 | R362: 57.4 | S362: 46 | T362: 1000 | U362: 252 | V362: 217 | W362: 6219 | X362: 3241.3844 | Y362: 280.5 | Z362: 1327 | AA362: 3085 | AB362: 303.1 | AC362: 1065 | AD362: 9824 | AE362: 1303 | AF362: 2409 | AG362: 115.6514
A363: 44354 | B363: =VLOOKUP(A363,'FTSE All-Share Historical '!A:B,2,FALSE) -> 4065.88 | C363: 856 | D363: 126.2 | E363: 389.2 | F363: 277 | G363: 95.8 | H363: 441 | I363: 93.2 | J363: 275 | K363: 307 | L363: 404.5 | M363: 1136 | N363: 314 | O363: 1580 | P363: 2220 | Q363: 113.4 | R363: 59 | S363: 46.5 | T363: 1005 | U363: 252 | V363: 218 | W363: 6141 | X363: 3153 | Y363: 273 | Z363: 1325 | AA363: 3120 | AB363: 308.2 | AC363: 1065 | AD363: 9862 | AE363: 1282.5 | AF363: 2425 | AG363: 112.6897
A364: 44355 | B364: =VLOOKUP(A364,'FTSE All-Share Historical '!A:B,2,FALSE) -> 4073.88 | C364: 888 | D364: 126 | E364: 397.2 | F364: 270 | G364: 96 | H364: 453 | I364: 94.2 | J364: 278 | K364: 306 | L364: 384 | M364: 1148 | N364: 315 | O364: 1600 | P364: 2200 | Q364: 113.2 | R364: 58.9 | S364: 46.2 | T364: 1015 | U364: 253 | V364: 214 | W364: 6192 | X364: 3183 | Y364: 268.5 | Z364: 1329 | AA364: 3095 | AB364: 301 | AC364: 1065 | AD364: 9880 | AE364: 1267.5 | AF364: 2418 | AG364: 104.9604
A365: 44356 | B365: =VLOOKUP(A365,'FTSE All-Share Historical '!A:B,2,FALSE) -> 4062.85 | C365: 850 | D365: 122.8 | E365: 388 | F365: 276 | G365: 97 | H365: 444 | I365: 93.15 | J365: 274.5 | K365: 319 | L365: 374 | M365: 1152 | N365: 311.2 | O365: 1605 | P365: 2185 | Q365: 112 | R365: 57.6 | S365: 46 | T365: 976 | U365: 251 | V365: 214 | W365: 6068 | X365: 3102.5 | Y365: 264 | Z365: 1330 | AA365: 3100 | AB365: 296.6 | AC365: 1065 | AD365: 9726 | AE365: 1290 | AF365: 2446 | AG365: 114.1345
A366: 44357 | B366: =VLOOKUP(A366,'FTSE All-Share Historical '!A:B,2,FALSE) -> 4061.37 | C366: 872 | D366: 125 | E366: 397.2 | F366: 279 | G366: 97.3 | H366: 443 | I366: 91 | J366: 275 | K366: 322 | L366: 379 | M366: 1208 | N366: 303.2 | O366: 1595 | P366: 2170 | Q366: 113.8 | R366: 57.2 | S366: 45.7 | T366: 1005 | U366: 250 | V366: 210 | W366: 6033 | X366: 3099.5 | Y366: 259 | Z366: 1279 | AA366: 3100 | AB366: 299 | AC366: 1065 | AD366: 9576 | AE366: 1271 | AF366: 2445 | AG366: 111.9674
A367: 44358 | B367: =VLOOKUP(A367,'FTSE All-Share Historical '!A:B,2,FALSE) -> 4086.98 | C367: 862 | D367: 125 | E367: 395 | F367: 270 | G367: 96 | H367: 444 | I367: 91.5 | J367: 275 | K367: 328 | L367: 374 | M367: 1246 | N367: 303.2 | O367: 1590 | P367: 2195 | Q367: 114.4 | R367: 57 | S367: 45.4 | T367: 998 | U367: 251 | V367: 211 | W367: 6119 | X367: 3147 | Y367: 265 | Z367: 1288 | AA367: 3100 | AB367: 303 | AC367: 1065 | AD367: 9572 | AE367: 1279 | AF367: 2447 | AG367: 110.7393
A368: 44361 | B368: =VLOOKUP(A368,'FTSE All-Share Historical '!A:B,2,FALSE) -> 4093.25 | C368: 868 | D368: 125 | E368: 394.6 | F368: 266 | G368: 96.7 | H368: 444 | I368: 89.9 | J368: 270 | K368: 330 | L368: 359 | M368: 1288 | N368: 299.4 | O368: 1580 | P368: 2215 | Q368: 117 | R368: 57.7 | S368: 46.2 | T368: 1010 | U368: 256 | V368: 214.5 | W368: 6092 | X368: 3112.5 | Y368: 269.5 | Z368: 1237 | AA368: 3105 | AB368: 299.2 | AC368: 1080 | AD368: 9622 | AE368: 1240 | AF368: 2465 | AG368: 111.3895
A369: 44362 | B369: =VLOOKUP(A369,'FTSE All-Share Historical '!A:B,2,FALSE) -> 4101.74 | C369: 850 | D369: 127.4 | E369: 398.8 | F369: 266 | G369: 98.6 | H369: 452 | I369: 90.3 | J369: 279 | K369: 336 | L369: 348.5 | M369: 1310 | N369: 297.4 | O369: 1600 | P369: 2205 | Q369: 116.4 | R369: 58 | S369: 46.4 | T369: 1030 | U369: 252 | V369: 211 | W369: 6014 | X369: 2999 | Y369: 259 | Z369: 1248 | AA369: 3095 | AB369: 291.1 | AC369: 1110 | AD369: 9818 | AE369: 1232.5 | AF369: 2486 | AG369: 126.3425
A370: 44363 | B370: =VLOOKUP(A370,'FTSE All-Share Historical '!A:B,2,FALSE) -> 4107.15 | C370: 874 | D370: 128 | E370: 405.8 | F370: 266 | G370: 99 | H370: 446 | I370: 91.2 | J370: 275 | K370: 328 | L370: 345 | M370: 1280 | N370: 293 | O370: 1590 | P370: 2220 | Q370: 118.6 | R370: 57.9 | S370: 46.5 | T370: 1020 | U370: 253 | V370: 210 | W370: 6020 | X370: 2963.5 | Y370: 254.5 | Z370: 1225 | AA370: 3140 | AB370: 296.7 | AC370: 1130 | AD370: 9914 | AE370: 1225 | AF370: 2512 | AG370: 126.1258
... A421: 44434 | B421: =VLOOKUP(A421,'FTSE All-Share Historical '!A:B,2,FALSE) -> 4121.23 | C421: 820 | D421: 174.1 | E421: 369 | F421: 275 | G421: 87 | H421: 421 | I421: 85.45 | J421: 337.5 | K421: 287 | L421: 360 | M421: 1450 | N421: 287.2 | O421: 1605 | P421: 2545 | Q421: 130.8 | R421: 61.7 | S421: 52.4 | T421: 1045 | U421: 283 | V421: 236 | W421: 5316 | X421: 2994 | Y421: 233.5 | Z421: 1115 | AA421: 3750 | AB421: 372.8 | AC421: 1030 | AD421: 10230 | AE421: 1174 | AF421: 2525 | AG421: 114.1345
A422: 44435 | B422: =VLOOKUP(A422,'FTSE All-Share Historical '!A:B,2,FALSE) -> 4135.49 | C422: 787 | D422: 169.2 | E422: 367 | F422: #N/A | G422: 84 | H422: 420 | I422: 85.45 | J422: 337 | K422: 295 | L422: 365.5 | M422: 1472 | N422: 289.8 | O422: 1615 | P422: 2580 | Q422: 128.6 | R422: 59.9 | S422: 52.4 | T422: 1045 | U422: 285 | V422: 241 | W422: 5404 | X422: 3084 | Y422: 241.5 | Z422: 1112 | AA422: 3795 | AB422: 369.5 | AC422: 1020 | AD422: 10225 | AE422: 1161.5 | AF422: 2524 | AG422: 111.9674
A423: 44439 | B423: =VLOOKUP(A423,'FTSE All-Share Historical '!A:B,2,FALSE) -> 4123.45 | C423: 774 | D423: 170.1 | E423: 363.6 | F423: 286 | G423: 86.4 | H423: 427 | I423: 86.35 | J423: 338.5 | K423: 298 | L423: 352.5 | M423: 1482 | N423: 294.6 | O423: 1605 | P423: 2570 | Q423: 128.6 | R423: 59 | S423: 54 | T423: 1115 | U423: 287 | V423: 238 | W423: 5382 | X423: 3069 | Y423: 250 | Z423: 1113 | AA423: 3820 | AB423: 363.1 | AC423: 1025 | AD423: 10505 | AE423: 1154 | AF423: 2538 | AG423: 110.3781
A424: 44440 | B424: =VLOOKUP(A424,'FTSE All-Share Historical '!A:B,2,FALSE) -> 4142.37 | C424: 770 | D424: 168.5 | E424: 356.6 | F424: 273 | G424: 86.4 | H424: 425 | I424: 87 | J424: 355 | K424: 302 | L424: 357.5 | M424: 1490 | N424: 295 | O424: 1610 | P424: 2635 | Q424: 127.4 | R424: 61.4 | S424: 54.8 | T424: 1095 | U424: 287 | V424: 237 | W424: 5332 | X424: 3067.5 | Y424: 242 | Z424: 1118 | AA424: 3910 | AB424: 365.4 | AC424: 1030 | AD424: 10565 | AE424: 1193 | AF424: 2560 | AG424: 110.8838
A425: 44441 | B425: =VLOOKUP(A425,'FTSE All-Share Historical '!A:B,2,FALSE) -> 4148.24 | C425: 744 | D425: 171.5 | E425: 355 | F425: 276 | G425: 88.6 | H425: 425 | I425: 85.85 | J425: 345 | K425: 316 | L425: 361 | M425: 1502 | N425: 292.6 | O425: 1630 | P425: 2645 | Q425: 127.8 | R425: 60.4 | S425: 56 | T425: 1050 | U425: 283 | V425: 237 | W425: 5406 | X425: 3074.5 | Y425: 242.5 | Z425: 1120 | AA425: 3900 | AB425: 357.2 | AC425: 1030 | AD425: 10645 | AE425: 1191 | AF425: 2565 | AG425: 111.1727
A426: 44442 | B426: =VLOOKUP(A426,'FTSE All-Share Historical '!A:B,2,FALSE) -> 4135.18 | C426: 726 | D426: 167.9 | E426: 355.8 | F426: 279 | G426: 87.6 | H426: 420 | I426: 84.5 | J426: 337 | K426: 299 | L426: 354 | M426: 1514 | N426: 285.4 | O426: 1620 | P426: 2685 | Q426: 129.8 | R426: 58.6 | S426: 59.6 | T426: 1060 | U426: 278 | V426: 239.5 | W426: 5408 | X426: 3091 | Y426: 237 | Z426: 1097 | AA426: 3935 | AB426: 351.3 | AC426: 1030 | AD426: 10610 | AE426: 1159.5 | AF426: 2572 | AG426: 111.1727
A427: 44445 | B427: =VLOOKUP(A427,'FTSE All-Share Historical '!A:B,2,FALSE) -> 4159.94 | C427: 726 | D427: 169.3 | E427: 351 | F427: 270 | G427: 85 | H427: 420 | I427: 84.35 | J427: 333 | K427: 300 | L427: 353 | M427: 1506 | N427: 285.2 | O427: 1590 | P427: 2610 | Q427: 129.2 | R427: 59.8 | S427: 56.2 | T427: 1050 | U427: 281 | V427: 249 | W427: 5337 | X427: 3078.5 | Y427: 239.5 | Z427: 1099 | AA427: 3965 | AB427: 349.9 | AC427: 1025 | AD427: 10765 | AE427: 1173 | AF427: 2603 | AG427: 110.5226
A428: 44446 | B428: =VLOOKUP(A428,'FTSE All-Share Historical '!A:B,2,FALSE) -> 4137.32 | C428: 730 | D428: 171 | E428: 351.4 | F428: 273 | G428: 87.9 | H428: 425 | I428: 82.25 | J428: 333 | K428: 299 | L428: 347 | M428: 1486 | N428: 283.4 | O428: 1595 | P428: 2570 | Q428: 128 | R428: 60.3 | S428: 55.4 | T428: 1045 | U428: 281.5 | V428: 247 | W428: 5360 | X428: 3096 | Y428: 239 | Z428: 1082 | AA428: 4010 | AB428: 347.2 | AC428: 1025 | AD428: 10700 | AE428: 1150.5 | AF428: 2576 | AG428: 111.245
A429: 44447 | B429: =VLOOKUP(A429,'FTSE All-Share Historical '!A:B,2,FALSE) -> 4104.05 | C429: 730 | D429: 170 | E429: 342.8 | F429: 279 | G429: 86.8 | H429: 425 | I429: 80.4 | J429: 331 | K429: 302 | L429: 338.5 | M429: 1476 | N429: 281 | O429: 1620 | P429: 2560 | Q429: 125 | R429: 58.7 | S429: 54.4 | T429: 1055 | U429: 277 | V429: 241 | W429: 5305 | X429: 3047.5 | Y429: 235 | Z429: 1056 | AA429: 4000 | AB429: 339.8 | AC429: 1025 | AD429: 10555 | AE429: 1135.5 | AF429: 2525 | AG429: 108.5
A430: 44448 | B430: =VLOOKUP(A430,'FTSE All-Share Historical '!A:B,2,FALSE) -> 4068.81 | C430: 750 | D430: 170.3 | E430: 330.4 | F430: 287 | G430: 86.4 | H430: 427 | I430: 81.15 | J430: 331 | K430: 305 | L430: 341 | M430: 1446 | N430: 271.4 | O430: 1620 | P430: 2590 | Q430: 125 | R430: 60.4 | S430: 54.2 | T430: 1040 | U430: 278 | V430: 243 | W430: 5163 | X430: 3028 | Y430: 231 | Z430: 1060 | AA430: 3910 | AB430: 340.5 | AC430: 1025 | AD430: 10575 | AE430: 1102.5 | AF430: 2520 | AG430: 112.8342
A431: 44449 | B431: =VLOOKUP(A431,'FTSE All-Share Historical '!A:B,2,FALSE) -> 4069.07 | C431: 768 | D431: 166.9 | E431: 309 | F431: 288 | G431: 86 | H431: 434 | I431: 80.7 | J431: 335 | K431: 302 | L431: 346 | M431: 1454 | N431: 268 | O431: 1590 | P431: 2580 | Q431: 124 | R431: 60.4 | S431: 54.6 | T431: 1015 | U431: 276.5 | V431: 243 | W431: 5264 | X431: 3071.5 | Y431: 233.5 | Z431: 1056 | AA431: 3870 | AB431: 340.2 | AC431: 1025 | AD431: 10570 | AE431: 1070 | AF431: 2531 | AG431: 126.8482
A432: 44452 | B432: =VLOOKUP(A432,'FTSE All-Share Historical '!A:B,2,FALSE) -> 4088.93 | C432: 740 | D432: 170.3 | E432: 301.8 | F432: 280 | G432: 83.6 | H432: 438 | I432: 82.8 | J432: 336 | K432: 303 | L432: 358 | M432: 1478 | N432: 270.8 | O432: 1590 | P432: 2550 | Q432: 124 | R432: 61.3 | S432: 53.6 | T432: 1020 | U432: 273 | V432: 250 | W432: 5287 | X432: 3093 | Y432: 232.5 | Z432: 1060 | AA432: 3845 | AB432: 355.4 | AC432: 1020 | AD432: 10640 | AE432: 1130.5 | AF432: 2500 | AG432: 125.6924
...
