Workbook
Name alloc_stu_grp: [1]stu_alloc!$B$2:$B$54
Name c_date: Report!$C$11
Name co_idx: [1]Report!$B$2
Name co_idx: Report!$B$2
Name co_idx: Report!$B$2
Name end_date: [1]Params!$B$7
Name Ex_code: Report!$B$4
Name Ex_code: Report!$B$4
Name Ex_code: Report!$B$1
Name exch_code: [1]Params!$B$4
Name Master_mode: [1]hparams!#REF!
Name Setup_status: #REF!
Name st_id: #REF!
Name start_date: [1]Params!$B$8
Name stu_grp: #REF!
Name stu_grp: #REF!
Name stu_idx: [1]hparams!$B$4
Name stu_key_id: [1]hparams!$B$3

Sheet Instructions
A2: Individual Report - Excel Workbook Template | D2: Write your company name, Code and Sector here
A3: Student Number: | B3: 25062677 - 10240511
B4: WORKBOOK TABS
A5: Instructions | B5: This page guides you through much of the preparation for the assignment.
A6: Co. Names | B6: List of all companies for which we have data and allocation to student. Please delete this sheet once you found your company. | D6: Company Name | F6: OXFORD NANOPORE TECHNOLOGIES PLC
A7: FTSE Data | B7: This has the daily cloing prices for a five year period, for the FTSE 350, FTSE-All shares, FTSE 100 Index for for comparison purposes, wherever applicable. | D7: Code | F7: ONT
A8: Example Data | B8: This has the daily share prices for a five year period, for the FTSE 350 (FTSEAS) and for each company being allocated. (Example) | D8: Sector | F8: Biotechnology and Life Sciences
A9: Report | B9: In this worksheet you will build your summary of the company analysis (for use in your word report).
A10: Ret_data | B10: You will calculate the daily returns on this sheet.
A11: IS data | B11: This is where you will paste 3 years of Income Statements .
A12: SoFP data | B12: This is where you will paste 3 years of Statements of Financial Position (Balance Sheets)
A13: Custom Data | B13: Get 3 years of ratios for your assigned company and its competitor.
A14: Mkt_calc | B14: This is where you will put all of your market analysis calculations (risk and return in relation to share price).
A15: Fin_Calc | B15: This is where you will put all of your financial analysis calculations (based on the data in the financial statements) and create relevant charts or tables .
B17: INSTRUCTIONS
A18: 1 | B18: In this tab input your student number.
A19: 2 | B19: In tab 'Report' for the company you have been allocated, insert the company code (that the exchange uses) the official company name, and the sector in which it operates.
A20: 3 | B20: In tab 'Ret_data' calculate the daily returns (%) from the historical daily prices (found in the 'Data' tab) for your company the FTSE All-Shares or FTSE350 and/or competitor. Time period is 01/01/2022 to 31/12/2024 (3 years)
A21: 4 | B21: Extract the Income statement (IS) data and Statements of financial position (SoFP) data for each year ending 2022-2025 (3 years of data). Paste the data into the tabs 'IS data' and 'SoFP data' respectively.
A22: 5 | B22: Extract the various ratios for your company and a competitor for the same time period. Paste the data into the 'Custom data' tab and analyse the data creating useful charts/tables.
A23: 6 | B23: In tab 'Mkt_calc' calculate; the daily volatility and average returns, the annual returns and the volatility in each year. Then calculate the overall returns for the whole five years. In this tab you should include the Beta and PE ratio (collected from Yahoo finance ). You will need this for section 3 of your word report ' Market report'.
A24: 7 | B24: In tab 'Fin_calc' perform the analysis - ratio analysis over time and in comparison . Create the charts and tables in this tab. You will need this for section 2 of your word report ' Financial report'.
A25: 8 | B25: In tab 'Report' put all charts and tables that you will be utilising in your word report, these will be duplicates of the charts and tables in 'Fin_calc' and 'Mkt_calc'. Make sure that you number them so that you can cross reference to your report.
A26: 9 | B26: Tidy up the workbook and make it presentable/professional.
A28: REMEMBER: | B28: Regularly save copies of the workbook adding a version number on each save.
B29: Look up the company on FAME, Hargreaves Lansdown and Yahoo finance, to find information about the company and the sector it operates in.

Sheet Sheet1

Sheet Co. Names
A1: Company name | B1: BvD sector | C1: Ticker symbol | E1: Students Allocation
A2: LEGAL & GENERAL GROUP PLC | B2: Banking, Insurance & Financial Services | C2: LGEN | E2: Phan Hoàng | F2: An | J2: Once you identified your company please delete this sheet
A3: ADMIRAL GROUP PLC | B3: Banking, Insurance & Financial Services | C3: ADM | E3: Trương Bùi Thành | F3: An
A4: INVESTEC PLC | B4: Banking, Insurance & Financial Services | C4: INVP | E4: Lê Nguyễn Vân | F4: Anh
A5: CMC MARKETS PLC | B5: Banking, Insurance & Financial Services | C5: CMCX | E5: Nguyễn Phương | F5: Anh
A6: GENUS PLC | B6: Biotechnology and Life Sciences | C6: GNS | E6: Trần Duy | F6: Bảo
A7: OXFORD NANOPORE TECHNOLOGIES PLC | B7: Biotechnology and Life Sciences | C7: ONT | E7: Nguyễn Thanh | F7: Bình
A8: CURRYS PLC | B8: Business Services | C8: CURY | E8: Đậu Minh | F8: Châu
A9: EASYJET PLC | B9: Business Services | C9: EZJ | E9: Hoàng Đức | F9: Cường
A10: MITIE GROUP PLC | B10: Business Services | C10: MTO | E10: Trần Minh | F10: Đăng
A11: ITV PLC | B11: Business Services | C11: ITV | E11: Lê Ngân | F11: Hà
A12: SEVERN TRENT PLC | B12: Business Services | C12: SVT | E12: Tăng Thu | F12: Hằng
A13: VODAFONE GROUP PUBLIC LIMITED COMPANY | B13: Communications | C13: VOD | E13: Nguyễn Xuân | F13: Hậu
A14: BT GROUP PLC | B14: Communications | C14: BT.A | E14: Đỗ Minh | F14: Hoàng
... A36: PRIMARY HEALTH PROPERTIES PLC | B36: Property Services | C36: PHP | E36: Nguyễn Thị Hà | F36: Vy
A37: WATCHES OF SWITZERLAND GROUP PLC | B37: Retail | C37: WOSG
A38: EMPIRIC STUDENT PROPERTY PLC | B38: Property Services | C38: ESP
A39: TRAVIS PERKINS PLC | B39: Retail | C39: TPK
A40: THG PLC | B40: Retail | C40: THG
A41: WATCHES OF SWITZERLAND GROUP PLC | B41: Retail | C41: WOSG
A42: WICKES GROUP PLC | B42: Retail | C42: WIX
A43: BAE SYSTEMS PLC | B43: Transport Manufacturing | C43: BA.
A44: CARNIVAL PLC | B44: Transport, Freight & Storage | C44: CCL
A45: FIRSTGROUP PLC | B45: Transport, Freight & Storage | C45: FGP
A46: WIZZ AIR HOLDINGS PLC | B46: Transport, Freight & Storage | C46: WIZZ
A47: J D WETHERSPOON PLC | B47: Travel, Personal & Leisure | C47: JDW
A48: CONVATEC GROUP PLC | B48: Travel, Personal & Leisure | C48: CTEC
... A51: ME GROUP INTERNATIONAL PLC | B51: Travel, Personal & Leisure | C51: MEGP

Sheet FTSE Data
D1: Notes: Please use this data for comparison purposes, wherever applicable
A3: Last Price (£)
A5: Start Date | B5: 44562
A6: End Date | B6: 45657
B8: FTSE 100 Index | C8: FTSE-All Shares | D8: FTSE 350 Index
A9: Dates | B9: UKX Index | C9: ASX Index | D9: NMX Index
A10: 44564 | B10: 7384.54 | C10: 4208.02 | D10: 4228.67
A11: 44565 | B11: 7505.15 | C11: 4276.18 | D11: 4298.76
A12: 44566 | B12: 7516.87 | C12: 4277.51 | D12: 4300.35
A13: 44567 | B13: 7450.37 | C13: 4235.63 | D13: 4257.77
A14: 44568 | B14: 7485.28 | C14: 4249.43 | D14: 4272.27
A15: 44571 | B15: 7445.25 | C15: 4219.71 | D15: 4242.3
A16: 44572 | B16: 7491.37 | C16: 4241.88 | D16: 4264.93
A17: 44573 | B17: 7551.72 | C17: 4270.79 | D17: 4294.04
A18: 44574 | B18: 7563.85 | C18: 4273.23 | D18: 4296.99
A19: 44575 | B19: 7542.95 | C19: 4256.59 | D19: 4280.34
A20: 44578 | B20: 7611.23 | C20: 4292.58 | D20: 4316.64
A21: 44579 | B21: 7563.55 | C21: 4263.04 | D21: 4287.22
... A791: 45657 | B791: 8173.02 | C791: 4467.8 | D791: 4510.61

Sheet My Data
B1: FTSE 350 Index | C1: ONT | D1: GNS
A2: Date | B2: Close | C2: Close | D2: Close
A3: 44564 | B3: 4228.67 | C3: ='Processed closing data'!K1 -> 6.98 | D3: ='Processed closing data'!L1 -> 49.38
A4: 44565 | B4: 4298.76 | C4: ='Processed closing data'!K2 -> 6.71 | D4: ='Processed closing data'!L2 -> 48.76
A5: 44566 | B5: 4300.35 | C5: ='Processed closing data'!K3 -> 6.33 | D5: ='Processed closing data'!L3 -> 48.14
A6: 44567 | B6: 4257.77 | C6: ='Processed closing data'!K4 -> 6.05 | D6: ='Processed closing data'!L4 -> 46.62
A7: 44568 | B7: 4272.27 | C7: ='Processed closing data'!K5 -> 6.05 | D7: ='Processed closing data'!L5 -> 46
A8: 44571 | B8: 4242.3 | C8: ='Processed closing data'!K6 -> 5.65 | D8: ='Processed closing data'!L6 -> 44.5
A9: 44572 | B9: 4264.93 | C9: ='Processed closing data'!K7 -> 5.31 | D9: ='Processed closing data'!L7 -> 44.32
A10: 44573 | B10: 4294.04 | C10: ='Processed closing data'!K8 -> 5.54 | D10: ='Processed closing data'!L8 -> 43.86
A11: 44574 | B11: 4296.99 | C11: ='Processed closing data'!K9 -> 5.51 | D11: ='Processed closing data'!L9 -> 41.92
A12: 44575 | B12: 4280.34 | C12: ='Processed closing data'!K10 -> 5.39 | D12: ='Processed closing data'!L10 -> 41.22
A13: 44578 | B13: 4316.64 | C13: ='Processed closing data'!K11 -> 5.48 | D13: ='Processed closing data'!L11 -> 41.74
A14: 44579 | B14: 4287.22 | C14: ='Processed closing data'!K12 -> 5.16 | D14: ='Processed closing data'!L12 -> 41.12
... A782: 45653 | B782: 4495.62 | C782: ='Processed closing data'!K780 -> 1.27 | D782: ='Processed closing data'!L780 -> 15.2
A783: 45656 | B783: 4479.42 | C783: 1.25 | D783: ='Processed closing data'!L781 -> 15.32
A784: 45657 | B784: 4510.61 | C784: 1.29 | D784: ='Processed closing data'!L782 -> 15.5

Sheet Processed closing data
A1: 44564 | B1: 4228.67 | C1: FTSE-350-Index | D1: 44565 | E1: 6.71 | F1: My Company | I1: =A1 -> 44564 | J1: =B1 -> 4228.67 | K1: 6.98 | L1: 49.38 | O1: 44565 | P1: 48.76 | Q1: Competitor
A2: 44565 | B2: 4298.76 | D2: 44566 | E2: 6.33 | I2: =A2 -> 44565 | J2: =B2 -> 4298.76 | K2: =_xlfn.XLOOKUP(VALUE(I2), 'Processed closing data'!D$1:D$750, 'Processed closing data'!E$1:E$750, "") -> 6.71 | L2: =_xlfn.XLOOKUP(VALUE(I2), 'Processed closing data'!O$1:O$750, 'Processed closing data'!P$1:P$750, "") -> 48.76 | O2: 44566 | P2: 48.14
A3: 44566 | B3: 4300.35 | D3: 44567 | E3: 6.05 | I3: =A3 -> 44566 | J3: =B3 -> 4300.35 | K3: =_xlfn.XLOOKUP(VALUE(I3), 'Processed closing data'!D$1:D$750, 'Processed closing data'!E$1:E$750, "") -> 6.33 | L3: =_xlfn.XLOOKUP(VALUE(I3), 'Processed closing data'!O$1:O$750, 'Processed closing data'!P$1:P$750, "") -> 48.14 | O3: 44567 | P3: 46.62
A4: 44567 | B4: 4257.77 | D4: 44568 | E4: 6.05 | I4: =A4 -> 44567 | J4: =B4 -> 4257.77 | K4: =_xlfn.XLOOKUP(VALUE(I4), 'Processed closing data'!D$1:D$750, 'Processed closing data'!E$1:E$750, "") -> 6.05 | L4: =_xlfn.XLOOKUP(VALUE(I4), 'Processed closing data'!O$1:O$750, 'Processed closing data'!P$1:P$750, "") -> 46.62 | O4: 44568 | P4: 46
A5: 44568 | B5: 4272.27 | D5: 44571 | E5: 5.65 | I5: =A5 -> 44568 | J5: =B5 -> 4272.27 | K5: =_xlfn.XLOOKUP(VALUE(I5), 'Processed closing data'!D$1:D$750, 'Processed closing data'!E$1:E$750, "") -> 6.05 | L5: =_xlfn.XLOOKUP(VALUE(I5), 'Processed closing data'!O$1:O$750, 'Processed closing data'!P$1:P$750, "") -> 46 | O5: 44571 | P5: 44.5
A6: 44571 | B6: 4242.3 | D6: 44572 | E6: 5.31 | I6: =A6 -> 44571 | J6: =B6 -> 4242.3 | K6: =_xlfn.XLOOKUP(VALUE(I6), 'Processed closing data'!D$1:D$750, 'Processed closing data'!E$1:E$750, "") -> 5.65 | L6: =_xlfn.XLOOKUP(VALUE(I6), 'Processed closing data'!O$1:O$750, 'Processed closing data'!P$1:P$750, "") -> 44.5 | O6: 44572 | P6: 44.32
A7: 44572 | B7: 4264.93 | D7: 44573 | E7: 5.54 | I7: =A7 -> 44572 | J7: =B7 -> 4264.93 | K7: =_xlfn.XLOOKUP(VALUE(I7), 'Processed closing data'!D$1:D$750, 'Processed closing data'!E$1:E$750, "") -> 5.31 | L7: =_xlfn.XLOOKUP(VALUE(I7), 'Processed closing data'!O$1:O$750, 'Processed closing data'!P$1:P$750, "") -> 44.32 | O7: 44573 | P7: 43.86
A8: 44573 | B8: 4294.04 | D8: 44574 | E8: 5.51 | I8: =A8 -> 44573 | J8: =B8 -> 4294.04 | K8: =_xlfn.XLOOKUP(VALUE(I8), 'Processed closing data'!D$1:D$750, 'Processed closing data'!E$1:E$750, "") -> 5.54 | L8: =_xlfn.XLOOKUP(VALUE(I8), 'Processed closing data'!O$1:O$750, 'Processed closing data'!P$1:P$750, "") -> 43.86 | O8: 44574 | P8: 41.92
A9: 44574 | B9: 4296.99 | D9: 44575 | E9: 5.39 | I9: =A9 -> 44574 | J9: =B9 -> 4296.99 | K9: =_xlfn.XLOOKUP(VALUE(I9), 'Processed closing data'!D$1:D$750, 'Processed closing data'!E$1:E$750, "") -> 5.51 | L9: =_xlfn.XLOOKUP(VALUE(I9), 'Processed closing data'!O$1:O$750, 'Processed closing data'!P$1:P$750, "") -> 41.92 | O9: 44575 | P9: 41.22
A10: 44575 | B10: 4280.34 | D10: 44578 | E10: 5.48 | I10: =A10 -> 44575 | J10: =B10 -> 4280.34 | K10: =_xlfn.XLOOKUP(VALUE(I10), 'Processed closing data'!D$1:D$750, 'Processed closing data'!E$1:E$750, "") -> 5.39 | L10: =_xlfn.XLOOKUP(VALUE(I10), 'Processed closing data'!O$1:O$750, 'Processed closing data'!P$1:P$750, "") -> 41.22 | O10: 44578 | P10: 41.74
A11: 44578 | B11: 4316.64 | D11: 44579 | E11: 5.16 | I11: =A11 -> 44578 | J11: =B11 -> 4316.64 | K11: =_xlfn.XLOOKUP(VALUE(I11), 'Processed closing data'!D$1:D$750, 'Processed closing data'!E$1:E$750, "") -> 5.48 | L11: =_xlfn.XLOOKUP(VALUE(I11), 'Processed closing data'!O$1:O$750, 'Processed closing data'!P$1:P$750, "") -> 41.74 | O11: 44579 | P11: 41.12
A12: 44579 | B12: 4287.22 | D12: 44580 | E12: 5.22 | I12: =A12 -> 44579 | J12: =B12 -> 4287.22 | K12: =_xlfn.XLOOKUP(VALUE(I12), 'Processed closing data'!D$1:D$750, 'Processed closing data'!E$1:E$750, "") -> 5.16 | L12: =_xlfn.XLOOKUP(VALUE(I12), 'Processed closing data'!O$1:O$750, 'Processed closing data'!P$1:P$750, "") -> 41.12 | O12: 44580 | P12: 40.92
A13: 44580 | B13: 4299.63 | D13: 44581 | E13: 5.46 | I13: =A13 -> 44580 | J13: =B13 -> 4299.63 | K13: =_xlfn.XLOOKUP(VALUE(I13), 'Processed closing data'!D$1:D$750, 'Processed closing data'!E$1:E$750, "") -> 5.22 | L13: =_xlfn.XLOOKUP(VALUE(I13), 'Processed closing data'!O$1:O$750, 'Processed closing data'!P$1:P$750, "") -> 40.92 | O13: 44581 | P13: 40.26
... A74: 44665 | B74: 4263.64 | D74: 44670 | E74: 3.44 | I74: =A74 -> 44665 | J74: =B74 -> 4263.64 | K74: =_xlfn.XLOOKUP(VALUE(I74), 'Processed closing data'!D$1:D$750, 'Processed closing data'!E$1:E$750, "") -> 3.54 | L74: =_xlfn.XLOOKUP(VALUE(I74), 'Processed closing data'!O$1:O$750, 'Processed closing data'!P$1:P$750, "") -> 26.54 | O74: 44670 | P74: 26.5
A75: 44666 | B75: 4263.64 | D75: 44671 | E75: 3.44 | I75: =A75 -> 44666 | J75: =B75 -> 4263.64 | K75: 3.54 | L75: 26.54 | O75: 44671 | P75: 26.46
A76: 44669 | B76: 4263.64 | D76: 44672 | E76: 3.56 | I76: =A76 -> 44669 | J76: =B76 -> 4263.64 | K76: 3.54 | L76: 26.54 | O76: 44672 | P76: 26.38
A77: 44670 | B77: 4251.45 | D77: 44673 | E77: 3.49 | I77: =A77 -> 44670 | J77: =B77 -> 4251.45 | K77: =_xlfn.XLOOKUP(VALUE(I77), 'Processed closing data'!D$1:D$750, 'Processed closing data'!E$1:E$750, "") -> 3.44 | L77: =_xlfn.XLOOKUP(VALUE(I77), 'Processed closing data'!O$1:O$750, 'Processed closing data'!P$1:P$750, "") -> 26.5 | O77: 44673 | P77: 26.58
A78: 44671 | B78: 4268.5 | D78: 44676 | E78: 3.19 | I78: =A78 -> 44671 | J78: =B78 -> 4268.5 | K78: =_xlfn.XLOOKUP(VALUE(I78), 'Processed closing data'!D$1:D$750, 'Processed closing data'!E$1:E$750, "") -> 3.44 | L78: =_xlfn.XLOOKUP(VALUE(I78), 'Processed closing data'!O$1:O$750, 'Processed closing data'!P$1:P$750, "") -> 26.46 | O78: 44676 | P78: 26.6
A79: 44672 | B79: 4270.31 | D79: 44677 | E79: 3.14 | I79: =A79 -> 44672 | J79: =B79 -> 4270.31 | K79: =_xlfn.XLOOKUP(VALUE(I79), 'Processed closing data'!D$1:D$750, 'Processed closing data'!E$1:E$750, "") -> 3.56 | L79: =_xlfn.XLOOKUP(VALUE(I79), 'Processed closing data'!O$1:O$750, 'Processed closing data'!P$1:P$750, "") -> 26.38 | O79: 44677 | P79: 26.3
A80: 44673 | B80: 4211.35 | D80: 44678 | E80: 3.18 | I80: =A80 -> 44673 | J80: =B80 -> 4211.35 | K80: =_xlfn.XLOOKUP(VALUE(I80), 'Processed closing data'!D$1:D$750, 'Processed closing data'!E$1:E$750, "") -> 3.49 | L80: =_xlfn.XLOOKUP(VALUE(I80), 'Processed closing data'!O$1:O$750, 'Processed closing data'!P$1:P$750, "") -> 26.58 | O80: 44678 | P80: 25.18
A81: 44676 | B81: 4135.79 | D81: 44679 | E81: 3.2 | I81: =A81 -> 44676 | J81: =B81 -> 4135.79 | K81: =_xlfn.XLOOKUP(VALUE(I81), 'Processed closing data'!D$1:D$750, 'Processed closing data'!E$1:E$750, "") -> 3.19 | L81: =_xlfn.XLOOKUP(VALUE(I81), 'Processed closing data'!O$1:O$750, 'Processed closing data'!P$1:P$750, "") -> 26.6 | O81: 44679 | P81: 25.4
A82: 44677 | B82: 4135.06 | D82: 44680 | E82: 3.07 | I82: =A82 -> 44677 | J82: =B82 -> 4135.06 | K82: =_xlfn.XLOOKUP(VALUE(I82), 'Processed closing data'!D$1:D$750, 'Processed closing data'!E$1:E$750, "") -> 3.14 | L82: =_xlfn.XLOOKUP(VALUE(I82), 'Processed closing data'!O$1:O$750, 'Processed closing data'!P$1:P$750, "") -> 26.3 | O82: 44680 | P82: 25.16
A83: 44678 | B83: 4151.93 | D83: 44684 | E83: 2.94 | I83: =A83 -> 44678 | J83: =B83 -> 4151.93 | K83: =_xlfn.XLOOKUP(VALUE(I83), 'Processed closing data'!D$1:D$750, 'Processed closing data'!E$1:E$750, "") -> 3.18 | L83: =_xlfn.XLOOKUP(VALUE(I83), 'Processed closing data'!O$1:O$750, 'Processed closing data'!P$1:P$750, "") -> 25.18 | O83: 44684 | P83: 24.46
A84: 44679 | B84: 4197.13 | D84: 44685 | E84: 2.8 | I84: =A84 -> 44679 | J84: =B84 -> 4197.13 | K84: =_xlfn.XLOOKUP(VALUE(I84), 'Processed closing data'!D$1:D$750, 'Processed closing data'!E$1:E$750, "") -> 3.2 | L84: =_xlfn.XLOOKUP(VALUE(I84), 'Processed closing data'!O$1:O$750, 'Processed closing data'!P$1:P$750, "") -> 25.4 | O84: 44685 | P84: 24
A85: 44680 | B85: 4216.64 | D85: 44686 | E85: 2.86 | I85: =A85 -> 44680 | J85: =B85 -> 4216.64 | K85: =_xlfn.XLOOKUP(VALUE(I85), 'Processed closing data'!D$1:D$750, 'Processed closing data'!E$1:E$750, "") -> 3.07 | L85: =_xlfn.XLOOKUP(VALUE(I85), 'Processed closing data'!O$1:O$750, 'Processed closing data'!P$1:P$750, "") -> 25.16 | O85: 44686 | P85: 23.98
A86: 44683 | B86: 4216.64 | D86: 44687 | E86: 2.71 | I86: =A86 -> 44683 | J86: =B86 -> 4216.64 | K86: 3.07 | L86: 25.16 | O86: 44687 | P86: 22.76
A87: 44684 | B87: 4218.6 | D87: 44690 | E87: 2.58 | I87: =A87 -> 44684 | J87: =B87 -> 4218.6 | K87: =_xlfn.XLOOKUP(VALUE(I87), 'Processed closing data'!D$1:D$750, 'Processed closing data'!E$1:E$750, "") -> 2.94 | L87: =_xlfn.XLOOKUP(VALUE(I87), 'Processed closing data'!O$1:O$750, 'Processed closing data'!P$1:P$750, "") -> 24.46 | O87: 44690 | P87: 22.34
A88: 44685 | B88: 4177.02 | D88: 44691 | E88: 2.55 | I88: =A88 -> 44685 | J88: =B88 -> 4177.02 | K88: =_xlfn.XLOOKUP(VALUE(I88), 'Processed closing data'!D$1:D$750, 'Processed closing data'!E$1:E$750, "") -> 2.8 | L88: =_xlfn.XLOOKUP(VALUE(I88), 'Processed closing data'!O$1:O$750, 'Processed closing data'!P$1:P$750, "") -> 24 | O88: 44691 | P88: 23.66
A89: 44686 | B89: 4177.55 | D89: 44692 | E89: 2.62 | I89: =A89 -> 44686 | J89: =B89 -> 4177.55 | K89: =_xlfn.XLOOKUP(VALUE(I89), 'Processed closing data'!D$1:D$750, 'Processed closing data'!E$1:E$750, "") -> 2.86 | L89: =_xlfn.XLOOKUP(VALUE(I89), 'Processed closing data'!O$1:O$750, 'Processed closing data'!P$1:P$750, "") -> 23.98 | O89: 44692 | P89: 24.38
A90: 44687 | B90: 4114.56 | D90: 44693 | E90: 2.55 | I90: =A90 -> 44687 | J90: =B90 -> 4114.56 | K90: =_xlfn.XLOOKUP(VALUE(I90), 'Processed closing data'!D$1:D$750, 'Processed closing data'!E$1:E$750, "") -> 2.71 | L90: =_xlfn.XLOOKUP(VALUE(I90), 'Processed closing data'!O$1:O$750, 'Processed closing data'!P$1:P$750, "") -> 22.76 | O90: 44693 | P90: 24.56
A91: 44690 | B91: 4017.43 | D91: 44694 | E91: 2.85 | I91: =A91 -> 44690 | J91: =B91 -> 4017.43 | K91: =_xlfn.XLOOKUP(VALUE(I91), 'Processed closing data'!D$1:D$750, 'Processed closing data'!E$1:E$750, "") -> 2.58 | L91: =_xlfn.XLOOKUP(VALUE(I91), 'Processed closing data'!O$1:O$750, 'Processed closing data'!P$1:P$750, "") -> 22.34 | O91: 44694 | P91: 25.44
A92: 44691 | B92: 4032.49 | D92: 44697 | E92: 2.9 | I92: =A92 -> 44691 | J92: =B92 -> 4032.49 | K92: =_xlfn.XLOOKUP(VALUE(I92), 'Processed closing data'!D$1:D$750, 'Processed closing data'!E$1:E$750, "") -> 2.55 | L92: =_xlfn.XLOOKUP(VALUE(I92), 'Processed closing data'!O$1:O$750, 'Processed closing data'!P$1:P$750, "") -> 23.66 | O92: 44697 | P92: 25.66
A93: 44692 | B93: 4090.08 | D93: 44698 | E93: 2.94 | I93: =A93 -> 44692 | J93: =B93 -> 4090.08 | K93: =_xlfn.XLOOKUP(VALUE(I93), 'Processed closing data'!D$1:D$750, 'Processed closing data'!E$1:E$750, "") -> 2.62 | L93: =_xlfn.XLOOKUP(VALUE(I93), 'Processed closing data'!O$1:O$750, 'Processed closing data'!P$1:P$750, "") -> 24.38 | O93: 44698 | P93: 25.44
A94: 44693 | B94: 4030.88 | D94: 44699 | E94: 2.8 | I94: =A94 -> 44693 | J94: =B94 -> 4030.88 | K94: =_xlfn.XLOOKUP(VALUE(I94), 'Processed closing data'!D$1:D$750, 'Processed closing data'!E$1:E$750, "") -> 2.55 | L94: =_xlfn.XLOOKUP(VALUE(I94), 'Processed closing data'!O$1:O$750, 'Processed closing data'!P$1:P$750, "") -> 24.56 | O94: 44699 | P94: 25.64
A95: 44694 | B95: 4132.07 | D95: 44700 | E95: 2.95 | I95: =A95 -> 44694 | J95: =B95 -> 4132.07 | K95: =_xlfn.XLOOKUP(VALUE(I95), 'Processed closing data'!D$1:D$750, 'Processed closing data'!E$1:E$750, "") -> 2.85 | L95: =_xlfn.XLOOKUP(VALUE(I95), 'Processed closing data'!O$1:O$750, 'Processed closing data'!P$1:P$750, "") -> 25.44 | O95: 44700 | P95: 25.8
A96: 44697 | B96: 4154.12 | D96: 44701 | E96: 3.23 | I96: =A96 -> 44697 | J96: =B96 -> 4154.12 | K96: =_xlfn.XLOOKUP(VALUE(I96), 'Processed closing data'!D$1:D$750, 'Processed closing data'!E$1:E$750, "") -> 2.9 | L96: =_xlfn.XLOOKUP(VALUE(I96), 'Processed closing data'!O$1:O$750, 'Processed closing data'!P$1:P$750, "") -> 25.66 | O96: 44701 | P96: 26.84
A97: 44698 | B97: 4183.88 | D97: 44704 | E97: 3.12 | I97: =A97 -> 44698 | J97: =B97 -> 4183.88 | K97: =_xlfn.XLOOKUP(VALUE(I97), 'Processed closing data'!D$1:D$750, 'Processed closing data'!E$1:E$750, "") -> 2.94 | L97: =_xlfn.XLOOKUP(VALUE(I97), 'Processed closing data'!O$1:O$750, 'Processed closing data'!P$1:P$750, "") -> 25.44 | O97: 44704 | P97: 26.78
A98: 44699 | B98: 4142.34 | D98: 44705 | E98: 3.17 | I98: =A98 -> 44699 | J98: =B98 -> 4142.34 | K98: =_xlfn.XLOOKUP(VALUE(I98), 'Processed closing data'!D$1:D$750, 'Processed closing data'!E$1:E$750, "") -> 2.8 | L98: =_xlfn.XLOOKUP(VALUE(I98), 'Processed closing data'!O$1:O$750, 'Processed closing data'!P$1:P$750, "") -> 25.64 | O98: 44705 | P98: 26.72
... A108: 44713 | B108: 4197.38 | D108: 44721 | E108: 3.57 | I108: =A108 -> 44713 | J108: =B108 -> 4197.38 | K108: =_xlfn.XLOOKUP(VALUE(I108), 'Processed closing data'!D$1:D$750, 'Processed closing data'!E$1:E$750, "") -> 3.08 | L108: =_xlfn.XLOOKUP(VALUE(I108), 'Processed closing data'!O$1:O$750, 'Processed closing data'!P$1:P$750, "") -> 26.74 | O108: 44721 | P108: 24.78
A109: 44714 | B109: 4197.38 | D109: 44722 | E109: 3.32 | I109: =A109 -> 44714 | J109: =B109 -> 4197.38 | K109: 3.08 | L109: 26.74 | O109: 44722 | P109: 24.74
...

Sheet IS data
A1: OXFORD NANOPORE TECHNOLOGIES PLC | I1: GENUS PLC - Competitor
B4: 31/12/2024 GBP | C4: 31/12/2023 GBP | D4: 31/12/2022 GBP | J4: 30/06/2024 GBP | K4: 30/06/2023 GBP | L4: 30/06/2022 GBP
A5: ∟ Turnover | B5: 183191000 | C5: 169668000 | D5: 198603000 | I5: ∟ Turnover | J5: 668800000 | K5: 689700000 | L5: 593400000
A6: ∟ National Turnover | B6: 21126000 | D6: 198603000 | I6: ∟ National Turnover | J6: 92300000 | K6: 93100000 | L6: 88700000
A7: ∟ Overseas Turnover | B7: 162065000 | I7: ∟ Overseas Turnover | J7: 576500000 | K7: 596600000 | L7: 504700000
A8: ∟ Cost of Sales | B8: -77796000 | C8: -79187000 | D8: -74793000 | I8: ∟ Cost of Sales
A9: ∟ Exceptional Items pre GP | I9: ∟ Exceptional Items pre GP
A10: ∟ Other Income pre GP | I10: ∟ Other Income pre GP
A11: ∟ Gross Profit | B11: 105395000 | C11: 90481000 | D11: 123810000 | I11: ∟ Gross Profit
A12: ∟ Administration Expenses | B12: -257728000 | C12: -259090000 | D12: -222289000 | I12: ∟ Administration Expenses | J12: -637800000 | K12: -645700000 | L12: -542000000
A13: ∟ Other Operating Income/Costs pre OP | I13: ∟ Other Operating Income/Costs pre OP
A14: ∟ Exceptional Items pre OP | I14: ∟ Exceptional Items pre OP | J14: -24600000 | K14: -3500000 | L14: -2000000
A15: ∟ Operating Profit | B15: -152333000 | C15: -168609000 | D15: -98479000 | I15: ∟ Operating Profit | J15: 6400000 | K15: 40500000 | L15: 49400000
A16: ∟ Other Income | B16: 1096000 | C16: 2194000 | D16: 10755000 | I16: ∟ Other Income | J16: 17400000 | K16: 13200000 | L16: 5200000
A17: ∟ Total Other Income & Int. Received | B17: 15937000 | C17: 21047000 | D17: 16696000 | I17: ∟ Total Other Income & Int. Received | J17: 21300000 | K17: 14300000 | L17: 5600000
A18: ∟ Exceptional Items | I18: ∟ Exceptional Items
A19: ∟ Profit (Loss) on Sale of Operations | I19: ∟ Profit (Loss) on Sale of Operations
A20: ∟ Costs of Reorganisation | I20: ∟ Costs of Reorganisation
A21: ∟ Profit (Loss) on Disposal | I21: ∟ Profit (Loss) on Disposal
A22: ∟ Other Exceptional Items | I22: ∟ Other Exceptional Items
A23: ∟ Profit (Loss) before Interest paid | B23: -136396000 | C23: -147562000 | D23: -81783000 | I23: ∟ Profit (Loss) before Interest paid | J23: 27700000 | K23: 54800000 | L23: 55000000
A24: ∟ Interest Received | B24: 14841000 | C24: 18853000 | D24: 5941000 | I24: ∟ Interest Received | J24: 3900000 | K24: 1100000 | L24: 400000
A25: ∟ Interest Paid | B25: -3565000 | C25: -2206000 | D25: -1628000 | I25: ∟ Interest Paid | J25: -22200000 | K25: -15400000 | L25: -6600000
A26: ∟ Paid to Bank | B26: -3 | C26: -1 | D26: -221 | I26: ∟ Paid to Bank | J26: -17800000 | K26: -12300000 | L26: -4100000
A27: ∟ Paid on Hire Purchase | I27: ∟ Paid on Hire Purchase
A28: ∟ Paid on Leasing | B28: -3562000 | C28: -2205000 | D28: -1407000 | I28: ∟ Paid on Leasing | J28: -2800000 | K28: -1200000 | L28: -1100000
A29: ∟ Other Interest Paid | I29: ∟ Other Interest Paid | J29: -1600000 | K29: -1900000 | L29: -1400000
A30: ∟ Net Interest | B30: 11276000 | C30: 16647000 | D30: 4313000 | I30: ∟ Net Interest | J30: -18300000 | K30: -14300000 | L30: -6200000
A31: ∟ Profit (Loss) before Tax | B31: -139961000 | C31: -149768000 | D31: -83411000 | I31: ∟ Profit (Loss) before Tax | J31: 5500000 | K31: 39400000 | L31: 48400000
A32: ∟ Taxation | B32: -6227000 | C32: -4739000 | D32: -7614000 | I32: ∟ Taxation | J32: -3100000 | K32: -7600000 | L32: -11700000
A33: ∟ Profit (Loss) after Tax | B33: -146188000 | C33: -154507000 | D33: -91025000 | I33: ∟ Profit (Loss) after Tax | J33: 2400000 | K33: 31800000 | L33: 36700000
A34: ∟ Extraordinary Items | I34: ∟ Extraordinary Items
A35: ∟ Minority Interests | I35: ∟ Minority Interests | J35: 5500000 | K35: 1500000 | L35: 4200000
A36: ∟ Profit (Loss) for period [=Net income] | B36: -146188000 | C36: -154507000 | D36: -91025000 | I36: ∟ Profit (Loss) for period [=Net income] | J36: 7900000 | K36: 33300000 | L36: 40900000
A37: ∟ Dividends (Distributable profit) | I37: ∟ Dividends (Distributable profit) | J37: -21000000 | K37: -21000000 | L37: -20900000
A38: ∟ Retained Profit(Loss) | B38: -146188000 | C38: -154507000 | D38: -91025000 | I38: ∟ Retained Profit(Loss) | J38: -13100000 | K38: 12300000 | L38: 20000000
A40: ∟ Depreciation | B40: 13449000 | C40: 18105000 | D40: 20443000 | I40: ∟ Depreciation | J40: 20100000 | K40: 30200000 | L40: 27300000
A41: ∟ Depreciation Owned Assets | B41: 12068000 | C41: 16496000 | D41: 15968000 | I41: ∟ Depreciation Owned Assets | J41: 18400000 | K41: 18400000 | L41: 14800000
A42: ∟ Depreciation Other Assets | B42: 1381000 | C42: 1609000 | D42: 4475000 | I42: ∟ Depreciation Other Assets | K42: 11800000 | L42: 11600000
A43: ∟ Impairment of Tangible Assets | I43: ∟ Impairment of Tangible Assets | J43: 1700000 | L43: 900000
...

Sheet SoFP data
A1: OXFORD NANOPORE TECHNOLOGIES PLC | I1: GENUS PLC - Competitor
B4: 31/12/2024 GBP | C4: 31/12/2023 GBP | D4: 31/12/2022 GBP | J4: 30/06/2024 GBP | K4: 30/06/2023 GBP | L4: 30/06/2022 GBP
A5: Fixed Assets | I5: Fixed Assets
A6: Tangible Assets | B6: 66331000 | C6: 49890000 | D6: 63200000 | I6: Tangible Assets | J6: 127300000 | K6: 164400000 | L6: 171400000
A7: ∟ Land & Buildings | B7: 4572000 | C7: 5524000 | D7: 5885000 | I7: ∟ Land & Buildings | J7: 81400000 | K7: 93100000 | L7: 88100000
A8: ∟ Freehold Land | I8: ∟ Freehold Land
A9: ∟ Leasehold Land | B9: 4572000 | C9: 5524000 | D9: 5885000 | I9: ∟ Leasehold Land
A10: ∟ Fixtures & Fittings | I10: ∟ Fixtures & Fittings
A11: ∟ Plant & Vehicles | B11: 16579000 | C11: 10463000 | D11: 8283000 | I11: ∟ Plant & Vehicles | K11: 54400000 | L11: 53700000
A12: ∟ Plant | B12: 16579000 | C12: 10463000 | D12: 8283000 | I12: ∟ Plant
A13: ∟ Vehicles | I13: ∟ Vehicles
A14: ∟ Other Fixed Assets | B14: 45180000 | C14: 33903000 | D14: 49032000 | I14: ∟ Other Fixed Assets | J14: 45900000 | K14: 16900000 | L14: 29600000
A15: Intangible Assets | B15: 78674000 | C15: 65436000 | D15: 30039000 | I15: Intangible Assets | J15: 230400000 | K15: 174000000 | L15: 183000000
A16: Investments & other fixed assets | B16: 76950000 | C16: 214553000 | D16: 92651000 | I16: Investments & other fixed assets | J16: 400100000 | K16: 410100000 | L16: 406000000
A17: ∟ Fixed Assets | B17: 221955000 | C17: 329879000 | D17: 185890000 | I17: ∟ Fixed Assets | J17: 757800000 | K17: 748500000 | L17: 760400000
A19: Current Assets | I19: Current Assets
A20: Stock & W.I.P. | B20: 99453000 | C20: 101548000 | D20: 87698000 | I20: Stock & W.I.P. | J20: 57100000 | K20: 61300000 | L20: 50900000
A21: ∟ Stock | B21: 37631000 | C21: 50888000 | D21: 41852000 | I21: ∟ Stock | J21: 24500000 | K21: 26600000 | L21: 24500000
A22: ∟ W.I.P. | B22: 45637000 | C22: 39154000 | D22: 34960000 | I22: ∟ W.I.P.
A23: ∟ Finished Goods | B23: 16185000 | C23: 11506000 | D23: 10886000 | I23: ∟ Finished Goods | J23: 32600000 | K23: 34700000 | L23: 26400000
A24: Trade Debtors | B24: 37537000 | C24: 33830000 | D24: 41181000 | I24: Trade Debtors | J24: 115200000 | K24: 113900000 | L24: 108700000
A25: Bank & Deposits | B25: 199517000 | C25: 220536000 | D25: 356778000 | I25: Bank & Deposits | J25: 42500000 | K25: 36300000 | L25: 38800000
A26: Other Current Assets | B26: 44735000 | C26: 41494000 | D26: 30872000 | I26: Other Current Assets | J26: 22100000 | K26: 22200000 | L26: 24800000
A27: ∟ Group Loans (asset) | I27: ∟ Group Loans (asset)
A28: ∟ Directors Loans (asset) | I28: ∟ Directors Loans (asset)
A29: ∟ Other Debtors | B29: 11652000 | C29: 14101000 | D29: 9986000 | I29: ∟ Other Debtors | J29: 10400000 | K29: 10500000 | L29: 12300000
A30: ∟ Prepayments | B30: 13519000 | C30: 13544000 | D30: 11738000 | I30: ∟ Prepayments | J30: 9600000 | K30: 7700000 | L30: 8500000
A31: ∟ Deferred Taxation | B31: 19564000 | C31: 13849000 | D31: 9148000 | I31: ∟ Deferred Taxation | J31: 2100000 | K31: 4000000 | L31: 4000000
A32: Investments & other current assets | B32: 138853000 | C32: 49775000 | D32: 121471000 | I32: Investments & other current assets | J32: 34200000 | K32: 25300000 | L32: 34300000
A33: ∟ Current Assets | B33: 520095000 | C33: 447183000 | D33: 638000000 | I33: ∟ Current Assets | J33: 271100000 | K33: 259000000 | L33: 257500000
A35: Current Liabilities | I35: Current Liabilities
A36: Trade Creditors | B36: -51966000 | C36: -40340000 | D36: -23103000 | I36: Trade Creditors | J36: -42100000 | K36: -34800000 | L36: -36000000
A37: Short Term Loans & Overdrafts | D37: -16011000 | I37: Short Term Loans & Overdrafts | J37: -4900000 | K37: -14200000 | L37: -17200000
A38: ∟ Bank Overdrafts | I38: ∟ Bank Overdrafts | J38: -4900000 | K38: -4200000 | L38: -7100000
A39: ∟ Group Loans (short t.) | I39: ∟ Group Loans (short t.)
A40: ∟ Director Loans (short t.) | I40: ∟ Director Loans (short t.)
A41: ∟ Hire Purch. & Leas. (short t.) | D41: -15049000 | I41: ∟ Hire Purch. & Leas. (short t.) | K41: -10000000 | L41: -10100000
A42: ∟ Hire Purchase (short t.) | I42: ∟ Hire Purchase (short t.)
A43: ∟ Leasing (short t.) | D43: -15049000 | I43: ∟ Leasing (short t.) | K43: -10000000 | L43: -10100000
A44: ∟ Other Short Term Loans | D44: -962 | I44: ∟ Other Short Term Loans
...

Sheet Ret_data
A1: Date | B1: ONT | C1: GNS | D1: FTSE-350-Index
A2: ='My Data'!A3 -> 44564 | B2: 0 | C2: 0 | D2: 0 | F2: Tính bằng cách lấy ln((03/01/2022) / (31/12/2021)) | J2: Formula for Daily returns = Ln (Pt/Pt-1)
A3: ='My Data'!A4 -> 44565 | B3: =LN('My Data'!C4/'My Data'!C3) -> -0.039449966 | C3: =LN('My Data'!D4/'My Data'!D3) -> -0.012635179 | D3: =LN('My Data'!B4/'My Data'!B3) -> 0.016439086
A4: ='My Data'!A5 -> 44566 | B4: =LN('My Data'!C5/'My Data'!C4) -> -0.058298715 | C4: =LN('My Data'!D5/'My Data'!D4) -> -0.012796872 | D4: =LN('My Data'!B5/'My Data'!B4) -> 0.00036980572 | M4: natural log = (current price / previous price)
A5: ='My Data'!A6 -> 44567 | B5: =LN('My Data'!C6/'My Data'!C5) -> -0.045241964 | C5: =LN('My Data'!D6/'My Data'!D5) -> -0.032083799 | D5: =LN('My Data'!B6/'My Data'!B5) -> -0.0099508657
A6: ='My Data'!A7 -> 44568 | B6: =LN('My Data'!C7/'My Data'!C6) -> 0 | C6: =LN('My Data'!D7/'My Data'!D6) -> -0.013388237 | D6: =LN('My Data'!B7/'My Data'!B6) -> 0.0033997529
A7: ='My Data'!A8 -> 44571 | B7: =LN('My Data'!C8/'My Data'!C7) -> -0.068402727 | C7: =LN('My Data'!D8/'My Data'!D7) -> -0.033152207 | D7: =LN('My Data'!B8/'My Data'!B7) -> -0.0070397269
A8: ='My Data'!A9 -> 44572 | B8: =LN('My Data'!C9/'My Data'!C8) -> -0.06206371 | C8: =LN('My Data'!D9/'My Data'!D8) -> -0.0040531467 | D8: =LN('My Data'!B9/'My Data'!B8) -> 0.0053201931
A9: ='My Data'!A10 -> 44573 | B9: =LN('My Data'!C10/'My Data'!C9) -> 0.042402666 | C9: =LN('My Data'!D10/'My Data'!D9) -> -0.010433299 | D9: =LN('My Data'!B10/'My Data'!B9) -> 0.0068022466
A10: ='My Data'!A11 -> 44574 | B10: =LN('My Data'!C11/'My Data'!C10) -> -0.0054298776 | C10: =LN('My Data'!D11/'My Data'!D10) -> -0.045239703 | D10: =LN('My Data'!B11/'My Data'!B10) -> 0.00068676285
A11: ='My Data'!A12 -> 44575 | B11: =LN('My Data'!C12/'My Data'!C11) -> -0.022019238 | C11: =LN('My Data'!D12/'My Data'!D11) -> -0.016839465 | D11: =LN('My Data'!B12/'My Data'!B11) -> -0.0038823319
A12: ='My Data'!A13 -> 44578 | B12: =LN('My Data'!C13/'My Data'!C12) -> 0.016559716 | C12: =LN('My Data'!D13/'My Data'!D12) -> 0.012536326 | D12: =LN('My Data'!B13/'My Data'!B12) -> 0.0084448762
A13: ='My Data'!A14 -> 44579 | B13: =LN('My Data'!C14/'My Data'!C13) -> -0.060168521 | C13: =LN('My Data'!D14/'My Data'!D13) -> -0.014965281 | D13: =LN('My Data'!B14/'My Data'!B13) -> -0.0068388176
A14: ='My Data'!A15 -> 44580 | B14: =LN('My Data'!C15/'My Data'!C14) -> 0.011560822 | C14: =LN('My Data'!D15/'My Data'!D14) -> -0.0048756801 | D14: =LN('My Data'!B15/'My Data'!B14) -> 0.0028904682 | K14: ln(Ngày sau / Ngày trước)
A15: ='My Data'!A16 -> 44581 | B15: =LN('My Data'!C16/'My Data'!C15) -> 0.044951388 | C15: =LN('My Data'!D16/'My Data'!D15) -> -0.016260521 | D15: =LN('My Data'!B16/'My Data'!B15) -> -7.2101826e-05
A16: ='My Data'!A17 -> 44582 | B16: =LN('My Data'!C17/'My Data'!C16) -> -0.0091996969 | C16: =LN('My Data'!D17/'My Data'!D16) -> -0.057246083 | D16: =LN('My Data'!B17/'My Data'!B16) -> -0.013384297
A17: ='My Data'!A18 -> 44585 | B17: =LN('My Data'!C18/'My Data'!C17) -> -0.11963317 | C17: =LN('My Data'!D18/'My Data'!D17) -> -0.044093164 | D17: =LN('My Data'!B18/'My Data'!B17) -> -0.028355706
A18: ='My Data'!A19 -> 44586 | B18: =LN('My Data'!C19/'My Data'!C18) -> -0.0104713 | C18: =LN('My Data'!D19/'My Data'!D18) -> -0.0077263078 | D18: =LN('My Data'!B19/'My Data'!B18) -> 0.009941783
A19: ='My Data'!A20 -> 44587 | B19: =LN('My Data'!C20/'My Data'!C19) -> 0.053291297 | C19: =LN('My Data'!D20/'My Data'!D19) -> 0.026784875 | D19: =LN('My Data'!B20/'My Data'!B19) -> 0.012790147
A20: ='My Data'!A21 -> 44588 | B20: =LN('My Data'!C21/'My Data'!C20) -> -0.051188247 | C20: =LN('My Data'!D21/'My Data'!D20) -> 0.017112717 | D20: =LN('My Data'!B21/'My Data'!B20) -> 0.0092897056
A21: ='My Data'!A22 -> 44589 | B21: =LN('My Data'!C22/'My Data'!C21) -> -0.051735674 | C21: =LN('My Data'!D22/'My Data'!D21) -> -0.016573488 | D21: =LN('My Data'!B22/'My Data'!B21) -> -0.011420759
A22: ='My Data'!A23 -> 44592 | B22: =LN('My Data'!C23/'My Data'!C22) -> 0.070466711 | C22: =LN('My Data'!D23/'My Data'!D22) -> 0.024495367 | D22: =LN('My Data'!B23/'My Data'!B22) -> 0.0019650988
A23: ='My Data'!A24 -> 44593 | B23: =LN('My Data'!C24/'My Data'!C23) -> 0.020408872 | C23: =LN('My Data'!D24/'My Data'!D23) -> 0.007859616 | D23: =LN('My Data'!B24/'My Data'!B23) -> 0.009758592
A24: ='My Data'!A25 -> 44594 | B24: =LN('My Data'!C25/'My Data'!C24) -> 0.029852963 | C24: =LN('My Data'!D25/'My Data'!D24) -> -0.011020841 | D24: =LN('My Data'!B25/'My Data'!B24) -> 0.0058177062
A25: ='My Data'!A26 -> 44595 | B25: =LN('My Data'!C26/'My Data'!C25) -> -0.023810649 | C25: =LN('My Data'!D26/'My Data'!D25) -> -0.050876772 | D25: =LN('My Data'!B26/'My Data'!B25) -> -0.0080931109
A26: ='My Data'!A27 -> 44596 | B26: =LN('My Data'!C27/'My Data'!C26) -> 0.0080000427 | C26: =LN('My Data'!D27/'My Data'!D26) -> 0.010494435 | D26: =LN('My Data'!B27/'My Data'!B26) -> -0.0033118662
... A783: ='My Data'!A784 -> 45657 | B783: =LN('My Data'!C784/'My Data'!C783) -> 0.031498667 | C783: =LN('My Data'!D784/'My Data'!D783) -> 0.01168086 | D783: =LN('My Data'!B784/'My Data'!B783) -> 0.0069388256

Sheet FTSE All-Share Historical 
A1: Date | B1: Price
A2: 43832 | B2: 4285.97
A3: 43833 | B3: 4290.29
A4: 43836 | B4: 4260.71
A5: 43837 | B5: 4262.43
A6: 43838 | B6: 4256.79
A7: 43839 | B7: 4267.27
A8: 43840 | B8: 4259.91
A9: 43843 | B9: 4278.83
A10: 43844 | B10: 4282.37
A11: 43845 | B11: 4290.42
A12: 43846 | B12: 4275.36
A13: 43847 | B13: 4311.06
... A1262: 45656 | B1262: 4479.42

Sheet Mkt_calc
B1: Equity Return and Risk
C2: ONT | D2: FTSE-350-Index | E2: GNS
B3: Average Daily Return | C3: =AVERAGE(Ret_data!B2:B783) -> -0.0021590878 | D3: =AVERAGE(Ret_data!D2:D783) -> 8.2538205e-05 | E3: =AVERAGE(Ret_data!C2:C783) -> -0.0014817205
B4: Volatility (StD) | C4: =STDEV(Ret_data!B2:B783) -> 0.035796841 | D4: =STDEV(Ret_data!D2:D783) -> 0.0079590321 | E4: =STDEV(Ret_data!C2:C783) -> 0.023658622
B5: 3 year return | C5: =C3*252*3 -> -1.6322704 | D5: =D3*252*3 -> 0.062398883 | E5: =E3*252*3 -> -1.1201807
A6: Annual return | B6: 2022 | C6: =AVERAGE(Ret_data!B2:B261)*252 -> -1.0068667 | D6: =AVERAGE(Ret_data!D2:D261)*252 -> -0.026697664 | E6: =AVERAGE(Ret_data!C2:C261)*252 -> -0.48819738
B7: 2023 | C7: =AVERAGE(Ret_data!B262:B521)*252 -> -0.16656256 | D7: =AVERAGE(Ret_data!D262:D521)*252 -> 0.036859854 | E7: =AVERAGE(Ret_data!C262:C521)*252 -> -0.30873636
B8: 2024 | C8: =AVERAGE(Ret_data!B522:B783)*252 -> -0.45949187 | D8: =AVERAGE(Ret_data!D522:D783)*252 -> 0.051996716 | E8: =AVERAGE(Ret_data!C522:C783)*252 -> -0.32362978
A9: Annual volatility | B9: 2022 | C9: =STDEV(Ret_data!B2:B261)*SQRT(252) -> 0.63817623 | D9: =STDEV(Ret_data!D2:D261)*SQRT(252) -> 0.16267515 | E9: =STDEV(Ret_data!C2:C261)*SQRT(252) -> 0.41185255
B10: 2023 | C10: =STDEV(Ret_data!B262:B521)*SQRT(252) -> 0.47956892 | D10: =STDEV(Ret_data!D262:D521)*SQRT(252) -> 0.11455636 | E10: =STDEV(Ret_data!C262:C521)*SQRT(252) -> 0.31637225
B11: 2024 | C11: =STDEV(Ret_data!B522:B783)*SQRT(252) -> 0.57659673 | D11: =STDEV(Ret_data!D522:D783)*SQRT(252) -> 0.092035658 | E11: =STDEV(Ret_data!C522:C783)*SQRT(252) -> 0.39287362
A13: FROM FAME
D14: ONT | E14: GNS
B15: Beta (3Y) | D15: 1.4 | E15: 1.24
B16: PE ratio (TTM) | C16: 2022 | D16: -22.31 | E16: 67.83
C17: 2023 | D17: -11.24 | E17: 54.05
C18: 2024 | D18: -7.91 | E18: 168.09

Sheet Fin_calc
A3: Profitability Ratios: Operating Profit Margin (%) | G3: Efficiency Ratios: Net Asset Turnover | M3: Gearing ratios: Gearing Ratio (%)
B4: Company | C4: Competitor | H4: Company | I4: Competitor | N4: Company | O4: Competitor
A5: 2022 | B5: =('IS data'!D15 / 'IS data'!D5) -> -0.49585857 | C5: =('IS data'!L15 / 'IS data'!L5) -> 0.083249073 | G5: 2022 | H5: ='IS data'!D5 / 'SoFP data'!D57 -> 0.27531822 | I5: ='IS data'!L5 / 'SoFP data'!L57 -> 0.68474498 | M5: 2022 | N5: =ABS('SoFP data'!D75) / (ABS('SoFP data'!D75) + ABS('SoFP data'!D90)) -> 0.038541196 | O5: =ABS('SoFP data'!L75) / (ABS('SoFP data'!L75) + ABS('SoFP data'!L90)) -> 0.33983383
A6: 2023 | B6: =('IS data'!C15 / 'IS data'!C5) -> -0.9937584 | C6: =('IS data'!K15 / 'IS data'!K5) -> 0.058721183 | G6: 2023 | H6: ='IS data'!C5 / 'SoFP data'!C57 -> 0.24665958 | I6: ='IS data'!K5 / 'SoFP data'!K57 -> 0.80169708 | M6: 2023 | N6: =ABS('SoFP data'!C75) / (ABS('SoFP data'!C75) + ABS('SoFP data'!C90)) -> 0.063983671 | O6: =ABS('SoFP data'!K75) / (ABS('SoFP data'!K75) + ABS('SoFP data'!K90)) -> 0.34069511
A7: 2024 | B7: =('IS data'!B15 / 'IS data'!B5) -> -0.83155286 | C7: =('IS data'!J15 / 'IS data'!J5) -> 0.009569378 | G7: 2024 | H7: ='IS data'!B5 / 'SoFP data'!B57 -> 0.29052112 | I7: ='IS data'!J5 / 'SoFP data'!J57 -> 0.76147102 | M7: 2024 | N7: =ABS('SoFP data'!B75) / (ABS('SoFP data'!B75) + ABS('SoFP data'!B90)) -> 0.070131312 | O7: =ABS('SoFP data'!J75) / (ABS('SoFP data'!J75) + ABS('SoFP data'!J90)) -> 0.38073551
A27: Equity Ratios: Return on Shareholder Funds (%) | G27: Liquidity ratios: Current Ratio
B28: Company | C28: Competitor | H28: Company | I28: Competitor
A29: 2022 | B29: =('IS data'!D31 / 'SoFP data'!D90) -> -0.1202657 | C29: =('IS data'!L31 / 'SoFP data'!L90) -> 0.084600594 | G29: 2022 | H29: ='SoFP data'!D33 / ABS('SoFP data'!D51) -> 6.2224476 | I29: ='SoFP data'!L33 / ABS('SoFP data'!L51) -> 1.7019167
A30: 2023 | B30: =('IS data'!C31 / 'SoFP data'!C90) -> -0.23261283 | C30: =('IS data'!K31 / 'SoFP data'!K90) -> 0.069464034 | G30: 2023 | H30: ='SoFP data'!C33 / ABS('SoFP data'!C51) -> 5.0133185 | I30: ='SoFP data'!K33 / ABS('SoFP data'!K51) -> 1.7595109
A31: 2024 | B31: =('IS data'!B31 / 'SoFP data'!B90) -> -0.23870361 | C31: =('IS data'!J31 / 'SoFP data'!J90) -> 0.010112153 | G31: 2024 | H31: ='SoFP data'!B33 / ABS('SoFP data'!B51) -> 4.6649475 | I31: ='SoFP data'!J33 / ABS('SoFP data'!J51) -> 1.8001328

Sheet Custom Data
A4: OXFORD NANOPORE TECHNOLOGIES PLC | H4: GENUS PLC - Competitor
B8: 31/12/2024 | C8: 31/12/2023 | D8: 31/12/2022 | I8: 30/06/2024 | J8: 30/06/2023 | K8: 30/06/2022
B9: GBP | C9: GBP | D9: GBP | I9: GBP | J9: GBP | K9: GBP
A10: Profitability ratios | H10: Profitability ratios
A11: ∟ Return on Shareholders Funds (%) | B11: -23.87 | C11: -23.26 | D11: -12.03 | H11: ∟ Return on Shareholders Funds (%) | I11: 1.01 | J11: 6.95 | K11: 8.46
A12: ∟ Return on Capital Employed (%) | B12: -22.2 | C12: -21.77 | D12: -11.56 | H12: ∟ Return on Capital Employed (%) | I12: 0.63 | J12: 4.58 | K12: 5.59
A13: ∟ Return on Total Assets (%) | B13: -18.86 | C13: -19.27 | D13: -10.12 | H13: ∟ Return on Total Assets (%) | I13: 0.53 | J13: 3.91 | K13: 4.75
A14: ∟ Profit margin (%) | B14: -76.4 | C14: -88.27 | D14: -42 | H14: ∟ Profit margin (%) | I14: 0.82 | J14: 5.71 | K14: 8.16
A15: ∟ Gross margin (%) | B15: 57.53 | C15: 53.33 | D15: 62.34 | H15: ∟ Gross margin (%)
A16: ∟ Berry ratio (x) | B16: 0.41 | C16: 0.35 | D16: 0.56 | H16: ∟ Berry ratio (x)
A17: ∟ EBIT margin (%) | B17: -83.16 | C17: -99.38 | D17: -49.59 | H17: ∟ EBIT margin (%) | I17: 0.96 | J17: 5.87 | K17: 8.32
A18: ∟ EBITDA margin (%) | B18: -59.53 | C18: -74.84 | D18: -33.54 | H18: ∟ EBITDA margin (%) | I18: 8.24 | J18: 12.19 | K18: 15.05
A20: Operational ratios | H20: Operational ratios
A21: ∟ Net Assets Turnover (x) | B21: 0.29 | C21: 0.25 | D21: 0.28 | H21: ∟ Net Assets Turnover (x) | I21: 0.76 | J21: 0.8 | K21: 0.68
A22: ∟ Fixed Assets Turnover (x) | B22: 0.83 | C22: 0.51 | D22: 1.07 | H22: ∟ Fixed Assets Turnover (x) | I22: 0.88 | J22: 0.92 | K22: 0.78
A23: ∟ Interest Cover (x) | B23: -38.26 | C23: -66.89 | D23: -50.24 | H23: ∟ Interest Cover (x) | I23: 1.25 | J23: 3.56 | K23: 8.33
A24: ∟ Stock Turnover (x) | B24: 1.84 | C24: 1.67 | D24: 2.26 | H24: ∟ Stock Turnover (x) | I24: 11.71 | J24: 11.25 | K24: 11.66
A25: ∟ Debtors Turnover (x) | B25: 4.88 | C25: 5.02 | D25: 4.82 | H25: ∟ Debtors Turnover (x) | I25: 5.81 | J25: 6.06 | K25: 5.46
A26: ∟ Debtor Collection (days) | B26: 74.79 | C26: 72.78 | D26: 75.68 | H26: ∟ Debtor Collection (days) | I26: 62.87 | J26: 60.28 | K26: 66.86
A27: ∟ Creditors Payment (days) | B27: 103.54 | C27: 86.78 | D27: 42.46 | H27: ∟ Creditors Payment (days) | I27: 22.98 | J27: 18.42 | K27: 22.14
A29: Structure ratios | H29: Structure ratios
A30: ∟ Current ratio (x) | B30: 4.66 | C30: 5.01 | D30: 6.22 | H30: ∟ Current ratio (x) | I30: 1.8 | J30: 1.76 | K30: 1.7
A31: ∟ Liquidity ratio (x) | B31: 3.77 | C31: 3.87 | D31: 5.37 | H31: ∟ Liquidity ratio (x) | I31: 1.42 | J31: 1.34 | K31: 1.37
A32: ∟ Shareholders liquidity ratio (x) | B32: 13.26 | C32: 14.63 | D32: 24.95 | H32: ∟ Shareholders liquidity ratio (x) | I32: 1.63 | J32: 1.94 | K32: 1.94
A33: ∟ Solvency ratio (Asset based) (%) | B33: 79.02 | C33: 82.86 | D33: 84.18 | H33: ∟ Solvency ratio (Asset based) (%) | I33: 52.86 | J33: 56.3 | K33: 56.2
A34: ∟ Solvency ratio (Liability based) (%) | B34: n.s. | C34: n.s. | D34: n.s. | H34: ∟ Solvency ratio (Liability based) (%) | I34: n.s. | J34: n.s. | K34: n.s.
A35: ∟ Asset Cover (x) | D35: 43.25 | H35: ∟ Asset Cover (x) | I35: 4.51 | J35: 4.62 | K35: 4.93
A36: ∟ Gearing (%) | B36: 7.54 | C36: 6.84 | D36: 6.32 | H36: ∟ Gearing (%) | I36: 62.38 | J36: 54.18 | K36: 54.48
A38: Per employee ratios | H38: Per employee ratios
A39: ∟ Profit per employee (unit) | B39: -106434 | C39: -132187 | D39: -90467 | H39: ∟ Profit per employee (unit) | I39: 1536 | J39: 10860 | K39: 13868
A40: ∟ Turnover per employee (unit) | B40: 139309 | C40: 149751 | D40: 215405 | H40: ∟ Turnover per employee (unit) | I40: 186763 | J40: 190105 | K40: 170029
A41: ∟ Salaries/Turnover | B41: 82.34 | C41: 89.31 | D41: 72.55 | H41: ∟ Salaries/Turnover | I41: 35.2 | J41: 33.3 | K41: 33.23
A42: ∟ Average Remuneration per employee (unit) | B42: 114710 | C42: 133738 | D42: 156278 | H42: ∟ Average Remuneration per employee (unit) | I42: 65736 | J42: 63313 | K42: 56504
A43: ∟ Shareholders Funds per employee (unit) | B43: n.s. | C43: n.s. | D43: n.s. | H43: ∟ Shareholders Funds per employee (unit) | I43: 151885 | J43: 156340 | K43: 163926
A44: ∟ Working Capital per employee (unit) | B44: 64657 | C44: 83882 | D44: 114725 | H44: ∟ Working Capital per employee (unit) | I44: 36359 | J44: 38699 | K44: 35415
A45: ∟ Total Assets per employee (unit) | B45: 564297 | C45: 685845 | D45: 893590 | H45: ∟ Total Assets per employee (unit) | I45: 287322 | J45: 277701 | K45: 291662

Sheet Report
A1: Code | B1: ONT
A2: Name | B2: OXFORD NANOPORE TECHNOLOGIES PLC
A3: Sector | B3: Biotechnology and Life Sciences
A6: Table 1 | B6: Key ratios of Oxford Nanopore Technologies
B7: Ratios | C7: 2022 | D7: 2023 | E7: 2024
B8: Operating Profit Margin (%) | C8: -0.4959 | D8: -0.9938 | E8: -0.8316
B9: Return on Shareholder Funds (%) | C9: -0.1203 | D9: -0.2326 | E9: -0.2387
B10: Net Assest Turnover | C10: 0.28 | D10: 0.25 | E10: 0.29
B11: Gearing Ratio | C11: 0.0418 | D11: 0.0734 | E11: 0.0816
B12: Current Ratio | C12: 6.22 | D12: 5.01 | E12: 4.66
A15: Table 2 | B15: Key Market Coefficients and Performance Metrics for ONT Shares
B16: Market CoEfficient | C16: 2022 | D16: 2023 | E16: 2024
B17: Annual Return (%) | C17: -1.0069 | D17: -0.1666 | E17: -0.4595
B18: Annual Volatility (%) | C18: 0.6382 | D18: 0.4796 | E18: 0.5766
B19: P/E Ratio | C19: -22.31 | D19: -11.24 | E19: -7.91
A22: Chart 1 | B22: Operating Profit Margin between ONT and GNS
A43: Chart 2 | B43: Current Ratio between ONT and GNS
A64: Chart 3 | B64: Gearing Ratio between ONT and GNS
A85: Chart 4 | B85: Return on Shareholder Funds between ONT and GNS
A108: Chart 5 | B108: Comparative Annual Returns Trend: ONT, GNS, and FTSE-350
A128: Chart 6 | B128: Comparative Annual Volatility Trend: ONT, GNS, and FTSE-350

Sheet IS Raw Data
B1: 31/12/2024 GBP | C1: 31/12/2023 GBP | D1: 31/12/2022 GBP
A2: Original documents | B2: 2024 12 months Cons. Unqualified IFRS | C2: 2023 12 months Cons. Unqualified IFRS | D2: 2022 12 months Cons. Unqualified IFRS
A3: ∟ Turnover | B3: 183,191,000 | C3: 169,668,000 | D3: 198,603,000
A4: ∟ National Turnover | B4: 21,126,000 | D4: 198,603,000
A5: ∟ Overseas Turnover | B5: 162,065,000
A6: ∟ Cost of Sales | B6: -77,796,000 | C6: -79,187,000 | D6: -74,793,000
A7: ∟ Exceptional Items pre GP
A8: ∟ Other Income pre GP
A9: ∟ Gross Profit | B9: 105,395,000 | C9: 90,481,000 | D9: 123,810,000
A10: ∟ Administration Expenses | B10: -257,728,000 | C10: -259,090,000 | D10: -222,289,000
A11: ∟ Other Operating Income/Costs pre OP
A12: ∟ Exceptional Items pre OP
A13: ∟ Operating Profit | B13: -152,333,000 | C13: -168,609,000 | D13: -98,479,000
A14: ∟ Other Income | B14: 1,096,000 | C14: 2,194,000 | D14: 10,755,000
A15: ∟ Total Other Income & Int. Received | B15: 15,937,000 | C15: 21,047,000 | D15: 16,696,000
A16: ∟ Exceptional Items
A17: ∟ Profit (Loss) on Sale of Operations
A18: ∟ Costs of Reorganisation
A19: ∟ Profit (Loss) on Disposal
A20: ∟ Other Exceptional Items
A21: ∟ Profit (Loss) before Interest paid | B21: -136,396,000 | C21: -147,562,000 | D21: -81,783,000
A22: ∟ Interest Received | B22: 14,841,000 | C22: 18,853,000 | D22: 5,941,000
A23: ∟ Interest Paid | B23: -3,565,000 | C23: -2,206,000 | D23: -1,628,000
A24: ∟ Paid to Bank | B24: -3 | C24: -1 | D24: -221
A25: ∟ Paid on Hire Purchase
A26: ∟ Paid on Leasing | B26: -3,562,000 | C26: -2,205,000 | D26: -1,407,000
A27: ∟ Other Interest Paid
A28: ∟ Net Interest | B28: 11,276,000 | C28: 16,647,000 | D28: 4,313,000
A29: ∟ Profit (Loss) before Tax | B29: -139,961,000 | C29: -149,768,000 | D29: -83,411,000
A30: ∟ Taxation | B30: -6,227,000 | C30: -4,739,000 | D30: -7,614,000
A31: ∟ Profit (Loss) after Tax | B31: -146,188,000 | C31: -154,507,000 | D31: -91,025,000
A32: ∟ Extraordinary Items
A33: ∟ Minority Interests
A34: ∟ Profit (Loss) for period [=Net income] | B34: -146,188,000 | C34: -154,507,000 | D34: -91,025,000
A35: ∟ Dividends (Distributable profit)
A36: ∟ Retained Profit(Loss) | B36: -146,188,000 | C36: -154,507,000 | D36: -91,025,000
A38: ∟ Depreciation | B38: 13,449,000 | C38: 18,105,000 | D38: 20,443,000
A39: ∟ Depreciation Owned Assets | B39: 12,068,000 | C39: 16,496,000 | D39: 15,968,000
A40: ∟ Depreciation Other Assets | B40: 1,381,000 | C40: 1,609,000 | D40: 4,475,000
A41: ∟ Impairment of Tangible Assets
...

Sheet SoFP Raw Data
B1: 31/12/2024 GBP | C1: 31/12/2023 GBP | D1: 31/12/2022 GBP
A2: Original documents | B2: 2024 12 months Cons. Unqualified IFRS | C2: 2023 12 months Cons. Unqualified IFRS | D2: 2022 12 months Cons. Unqualified IFRS
A3: Fixed Assets
A4: Tangible Assets | B4: 66,331,000 | C4: 49,890,000 | D4: 63,200,000
A5: ∟ Land & Buildings | B5: 4,572,000 | C5: 5,524,000 | D5: 5,885,000
A6: ∟ Freehold Land
A7: ∟ Leasehold Land | B7: 4,572,000 | C7: 5,524,000 | D7: 5,885,000
A8: ∟ Fixtures & Fittings
A9: ∟ Plant & Vehicles | B9: 16,579,000 | C9: 10,463,000 | D9: 8,283,000
A10: ∟ Plant | B10: 16,579,000 | C10: 10,463,000 | D10: 8,283,000
A11: ∟ Vehicles
A12: ∟ Other Fixed Assets | B12: 45,180,000 | C12: 33,903,000 | D12: 49,032,000
A13: Intangible Assets | B13: 78,674,000 | C13: 65,436,000 | D13: 30,039,000
A14: Investments & other fixed assets | B14: 76,950,000 | C14: 214,553,000 | D14: 92,651,000
A15: ∟ Fixed Assets | B15: 221,955,000 | C15: 329,879,000 | D15: 185,890,000
A17: Current Assets
A18: Stock & W.I.P. | B18: 99,453,000 | C18: 101,548,000 | D18: 87,698,000
A19: ∟ Stock | B19: 37,631,000 | C19: 50,888,000 | D19: 41,852,000
A20: ∟ W.I.P. | B20: 45,637,000 | C20: 39,154,000 | D20: 34,960,000
A21: ∟ Finished Goods | B21: 16,185,000 | C21: 11,506,000 | D21: 10,886,000
A22: Trade Debtors | B22: 37,537,000 | C22: 33,830,000 | D22: 41,181,000
A23: Bank & Deposits | B23: 199,517,000 | C23: 220,536,000 | D23: 356,778,000
A24: Other Current Assets | B24: 44,735,000 | C24: 41,494,000 | D24: 30,872,000
A25: ∟ Group Loans (asset)
A26: ∟ Directors Loans (asset)
A27: ∟ Other Debtors | B27: 11,652,000 | C27: 14,101,000 | D27: 9,986,000
A28: ∟ Prepayments | B28: 13,519,000 | C28: 13,544,000 | D28: 11,738,000
A29: ∟ Deferred Taxation | B29: 19,564,000 | C29: 13,849,000 | D29: 9,148,000
A30: Investments & other current assets | B30: 138,853,000 | C30: 49,775,000 | D30: 121,471,000
A31: ∟ Current Assets | B31: 520,095,000 | C31: 447,183,000 | D31: 638,000,000
A33: Current Liabilities
A34: Trade Creditors | B34: -51,966,000 | C34: -40,340,000 | D34: -23,103,000
A35: Short Term Loans & Overdrafts | D35: -16,011,000
A36: ∟ Bank Overdrafts
A37: ∟ Group Loans (short t.)
A38: ∟ Director Loans (short t.)
A39: ∟ Hire Purch. & Leas. (short t.) | D39: -15,049,000
A40: ∟ Hire Purchase (short t.)
A41: ∟ Leasing (short t.) | D41: -15,049,000
A42: ∟ Other Short Term Loans | D42: -962
...

Sheet Closing Price Raw Data
A1: 45657 | B1: 1.29 | E1: 1.29
A2: 45656 | B2: 1.25 | E2: 1.25
A3: 45653 | B3: 1.27 | E3: 1.27
A4: 45650 | B4: 1.35 | E4: 1.35
A5: 45649 | B5: 1.29 | E5: 1.29
A6: 45646 | B6: 1.43 | E6: 1.43
A7: 45645 | B7: 1.38 | E7: 1.38
A8: 45644 | B8: 1.43 | E8: 1.43
A9: 45643 | B9: 1.53 | E9: 1.53
A10: 45642 | B10: 1.57 | E10: 1.57
A11: 45639 | B11: 1.55 | E11: 1.55
A12: 45638 | B12: 1.55 | E12: 1.55
... A114: 45495 | B114: 1.20 | E114: 1.20
A115: 45492 | B115: 45839 | E115: 45839
A116: 45491 | B116: 45962 | E116: 45962
A117: 45490 | B117: 45931 | E117: 45931
A118: 45489 | B118: 45778 | E118: 45778
A119: 45488 | B119: 45778 | E119: 45778
A120: 45485 | B120: 45778 | E120: 45778
A121: 45484 | B121: 45809 | E121: 45809
A122: 45483 | B122: 45778 | E122: 45778
A123: 45482 | B123: 45658 | E123: 45658
A124: 45481 | B124: 45748 | E124: 45748
A125: 45478 | B125: 45778 | E125: 45778
A126: 45477 | B126: 45778 | E126: 45778
A127: 45476 | B127: 45689 | E127: 45689
A128: 45475 | B128: 0.99 | E128: 0.99
A129: 45474 | B129: 0.98 | E129: 0.98
A130: 45471 | B130: 0.94 | E130: 0.94
A131: 45470 | B131: 0.98 | E131: 0.98
A132: 45469 | B132: 0.90 | E132: 0.90
A133: 45468 | B133: 0.87 | E133: 0.87
A134: 45467 | B134: 0.87 | E134: 0.87
A135: 45464 | B135: 0.92 | E135: 0.92
A136: 45463 | B136: 0.97 | E136: 0.97
A137: 45462 | B137: 0.97 | E137: 0.97
A138: 45461 | B138: 0.97 | E138: 0.97
A139: 45460 | B139: 0.97 | E139: 0.97
... A141: 45456 | B141: 0.98 | E141: 0.98
A142: 45455 | B142: 45717 | E142: 45717
...

Sheet All stock Data
C1: XLON:FSTA | D1: XLON:GFRD | E1: XLON:HFD | F1: XLON:BOOT | G1: XLON:HSW | H1: XLON:KMR | I1: XLON:MARS | J1: XLON:MOTR | K1: XLON:NXR | L1: XLON:OTB | M1: XLON:OXB | N1: XLON:MAB | O1: XLON:YNGA | P1: XLON:MGNS | Q1: XLON:KIE | R1: XLON:COST | S1: XLON:VTU | T1: XLON:VCP | U1: XLON:JHD | V1: XLON:WJG | W1: XLON:RIO | X1: XLON:AAL | Y1: XLON:CAML | Z1: XLON:JDW | AA1: XLON:CKN | AB1: XLON:BAB | AC1: XLON:OCN | AD1: XLON:FERG | AE1: XLON:JET2 | AF1: XLON:HIK | AG1: XLON:SNG
A2: Date | C2: Close | D2: Close | E2: Close | F2: Close | G2: Close | H2: Close | I2: Close | J2: Close | K2: Close | L2: Close | M2: Close | N2: Close | O2: Close | P2: Close | Q2: Close | R2: Close | S2: Close | T2: Close | U2: Close | V2: Close | W2: Close | X2: Close | Y2: Close | Z2: Close | AA2: Close | AB2: Close | AC2: Close | AD2: Close | AE2: Close | AF2: Close | AG2: Close
A3: 43832 | B3: =VLOOKUP(A3,'FTSE All-Share Historical '!A:B,2,FALSE) -> 4285.97 | C3: 960 | D3: 886 | E3: 170.3 | F3: 330 | G3: 128.8 | H3: 239 | I3: 129.6 | J3: 289 | K3: 278 | L3: 489.2 | M3: 673 | N3: 456.5 | O3: 1627.5 | P3: 1620 | Q3: 94.75 | R3: 165 | S3: 38.3 | T3: 432.5 | U3: 270.5 | V3: 244 | W3: 4526.5 | X3: 2193.1259 | Y3: 223 | Z3: 1678 | AA3: 3030 | AB3: 631 | AC3: 990 | AD3: 6978 | AE3: 1723 | AF3: 1985 | AG3: 4.2439
A4: 43833 | B4: =VLOOKUP(A4,'FTSE All-Share Historical '!A:B,2,FALSE) -> 4290.29 | C4: 940 | D4: 165.86 | E4: 167.8 | F4: 322 | G4: 128.8 | H4: 239 | I4: 128.2 | J4: 294 | K4: 276 | L4: 490 | M4: 670 | N4: 456.5 | O4: 1650 | P4: 1610 | Q4: 91.7 | R4: 166.6 | S4: 37 | T4: 434 | U4: 266 | V4: 246 | W4: 4504 | X4: 2177.6884 | Y4: 221 | Z4: 1676 | AA4: 2995 | AB4: 613 | AC4: 990 | AD4: 7006 | AE4: 1675 | AF4: 1986 | AG4: 4.6051
A5: 43836 | B5: =VLOOKUP(A5,'FTSE All-Share Historical '!A:B,2,FALSE) -> 4260.71 | C5: 950 | D5: 163 | E5: 162.3 | F5: 330 | G5: 127.8 | H5: 241 | I5: 125.7 | J5: 290 | K5: 280 | L5: 478 | M5: 675 | N5: 443 | O5: 1660 | P5: 1580 | Q5: 90.5 | R5: 164.2 | S5: 36.4 | T5: 432.5 | U5: 269 | V5: 244 | W5: 4430 | X5: 2136.3557 | Y5: 216 | Z5: 1644 | AA5: 2935 | AB5: 628.4 | AC5: 995 | AD5: 6906 | AE5: 1674 | AF5: 1912 | AG5: 4.4245
A6: 43837 | B6: =VLOOKUP(A6,'FTSE All-Share Historical '!A:B,2,FALSE) -> 4262.43 | C6: 966 | D6: 136.42 | E6: 159.9 | F6: 330 | G6: 130.4 | H6: 245 | I6: 125 | J6: 288 | K6: 280 | L6: 481.8 | M6: 670 | N6: 439.5 | O6: 1637.5 | P6: 1616 | Q6: 89.5 | R6: 167 | S6: 37.1 | T6: 435 | U6: 273 | V6: 244 | W6: 4440 | X6: 2151.2952 | Y6: 215.5 | Z6: 1626 | AA6: 2955 | AB6: 646.6 | AC6: 995 | AD6: 6948 | AE6: 1670 | AF6: 1882.5 | AG6: 4.3703
A7: 43838 | B7: =VLOOKUP(A7,'FTSE All-Share Historical '!A:B,2,FALSE) -> 4256.79 | C7: 958 | D7: 144.08 | E7: 158 | F7: 320 | G7: 130 | H7: 240.5 | I7: 122.7 | J7: 290 | K7: 280 | L7: 468.4 | M7: 665 | N7: 421.5 | O7: 1605 | P7: 1640 | Q7: 87.05 | R7: 166.6 | S7: 36.9 | T7: 438 | U7: 268 | V7: 242.5 | W7: 4500 | X7: 2144.3234 | Y7: 217 | Z7: 1625 | AA7: 2945 | AB7: 641 | AC7: 990 | AD7: 6980 | AE7: 1675 | AF7: 1874.5 | AG7: 4.6954
A8: 43839 | B8: =VLOOKUP(A8,'FTSE All-Share Historical '!A:B,2,FALSE) -> 4267.27 | C8: 956 | D8: 151.5 | E8: 154.1 | F8: 315 | G8: 133 | H8: 235 | I8: 123.1 | J8: 278 | K8: 283.5 | L8: 461 | M8: 675 | N8: 433 | O8: 1650 | P8: 1652 | Q8: 83.1 | R8: 162.6 | S8: 37.35 | T8: 437.5 | U8: 270 | V8: 242 | W8: 4451 | X8: 2135.3597 | Y8: 224.5 | Z8: 1622 | AA8: 2925 | AB8: 643.2 | AC8: 980 | AD8: 7146 | AE8: 1705 | AF8: 1902 | AG8: 4.6051
A9: 43840 | B9: =VLOOKUP(A9,'FTSE All-Share Historical '!A:B,2,FALSE) -> 4259.91 | C9: 962 | D9: 158.4 | E9: 142 | F9: 313 | G9: 136 | H9: 233 | I9: 121.2 | J9: 277 | K9: 283 | L9: 461 | M9: 690 | N9: 433 | O9: 1630 | P9: 1664 | Q9: 82.5 | R9: 166 | S9: 37.25 | T9: 432 | U9: 270 | V9: 242 | W9: 4488 | X9: 2156.2751 | Y9: 222 | Z9: 1605 | AA9: 2925 | AB9: 636 | AC9: 980 | AD9: 7078 | AE9: 1817 | AF9: 1906.5 | AG9: 4.4606
A10: 43843 | B10: =VLOOKUP(A10,'FTSE All-Share Historical '!A:B,2,FALSE) -> 4278.83 | C10: 978 | D10: 157.7 | E10: 146 | F10: 313 | G10: 144 | H10: 240 | I10: 118.4 | J10: 286 | K10: 289 | L10: 464 | M10: 700 | N10: 420.5 | O10: 1622.5 | P10: 1648 | Q10: 83.8 | R10: 168.6 | S10: 37 | T10: 440 | U10: 278 | V10: 241.5 | W10: 4555 | X10: 2176.6924 | Y10: 228 | Z10: 1600 | AA10: 2925 | AB10: 638.4 | AC10: 975 | AD10: 7166 | AE10: 1806 | AF10: 1928 | AG10: 4.4606
A11: 43844 | B11: =VLOOKUP(A11,'FTSE All-Share Historical '!A:B,2,FALSE) -> 4282.37 | C11: 961 | D11: 158.26 | E11: 146 | F11: 325 | G11: 143.6 | H11: 235 | I11: 120.8 | J11: 295 | K11: 290 | L11: 450.2 | M11: 695 | N11: 425 | O11: 1620 | P11: 1646 | Q11: 81.95 | R11: 170.2 | S11: 36.7 | T11: 440 | U11: 275 | V11: 248 | W11: 4545 | X11: 2163.7448 | Y11: 230 | Z11: 1599 | AA11: 2905 | AB11: 632.6 | AC11: 980 | AD11: 7216 | AE11: 1803 | AF11: 1944.5 | AG11: 4.9121
A12: 43845 | B12: =VLOOKUP(A12,'FTSE All-Share Historical '!A:B,2,FALSE) -> 4290.42 | C12: 970 | D12: 151.86 | E12: 145.5 | F12: 335 | G12: 149.8 | H12: 236 | I12: 122.3 | J12: 294 | K12: 285 | L12: 457 | M12: 700 | N12: 417 | O12: 1610 | P12: 1680 | Q12: 77.5 | R12: 165.2 | S12: 36.1 | T12: 437.5 | U12: 281 | V12: 248.5 | W12: 4523 | X12: 2152.7892 | Y12: 228 | Z12: 1600 | AA12: 2950 | AB12: 618.8 | AC12: 1000 | AD12: 7176 | AE12: 1820 | AF12: 1975 | AG12: 5.0927
A13: 43846 | B13: =VLOOKUP(A13,'FTSE All-Share Historical '!A:B,2,FALSE) -> 4275.36 | C13: 970 | D13: 145.98 | E13: 153.5 | F13: 328 | G13: 149.4 | H13: 235 | I13: 123.4 | J13: 300 | K13: 281 | L13: 455.8 | M13: 671 | N13: 412.5 | O13: 1630 | P13: 1716 | Q13: 78 | R13: 170.4 | S13: 36.8 | T13: 437.5 | U13: 281 | V13: 250 | W13: 4526.5 | X13: 2166.7327 | Y13: 220.5 | Z13: 1600 | AA13: 3010 | AB13: 609.8 | AC13: 1025 | AD13: 7170 | AE13: 1777 | AF13: 1910.5 | AG13: 5.9596
A14: 43847 | B14: =VLOOKUP(A14,'FTSE All-Share Historical '!A:B,2,FALSE) -> 4311.06 | C14: 970 | D14: 142.88 | E14: 152 | F14: 342 | G14: 153.2 | H14: 237 | I14: 121.3 | J14: 304 | K14: 290 | L14: 437 | M14: 679 | N14: 411 | O14: 1625 | P14: 1696 | Q14: 78.4 | R14: 175.6 | S14: 38.15 | T14: 440 | U14: 279 | V14: 255 | W14: 4651 | X14: 2236.4506 | Y14: 224.5 | Z14: 1623 | AA14: 3075 | AB14: 620.2 | AC14: 1025 | AD14: 7176 | AE14: 1792 | AF14: 1955.5 | AG14: 5.779
