Workbook

Sheet UK
A1: Date | B1: r_GB | C1: Dy_GB | D1: r_GB(-1) | E1: Dy_GB(-1) | F1: r_GB(-1) #2
A2: 1984 | B2: 15.919408 | C2: 2.4776165 | H2: r_GB | J2: Dy_GB
A3: 1985 | B3: 7.5916845 | C3: 3.3091661 | D3: =B2 -> 15.919408 | E3: =C2 -> 2.4776165 | F3: 15.919408 | N3: r_GB | O3: Frequency | R3: Dy_GB | S3: Frequency
A4: 1986 | B4: 13.849031 | C4: 3.702316 | D4: =B3 -> 7.5916845 | E4: =C3 -> 3.3091661 | F4: 7.5916845 | H4: Mean | I4: 2.0438729 | J4: Mean | K4: 1.6482851 | N4: -45 | O4: {=FREQUENCY(B2:B42,N4:N19)} -> 0 | R4: -15 | S4: {=FREQUENCY(C2:C42,R4:R16)} -> 0
A5: 1987 | B5: -2.1616529 | C5: 4.2484411 | D5: =B4 -> 13.849031 | E5: =C4 -> 3.702316 | F5: 13.849031 | H5: Standard Error | I5: 2.2143809 | J5: Standard Error | K5: 0.45463002 | N5: -40 | O5: 1 | R5: -12.5 | S5: 0
A6: 1988 | B6: 0.43213757 | C6: 4.687521 | D6: =B5 -> -2.1616529 | E6: =C5 -> 4.2484411 | F6: -2.1616529 | H6: Median | I6: 6.1234335 | J6: Median | K6: 1.9954995 | N6: -35 | O6: 0 | R6: -10 | S6: 1
A7: 1989 | B7: 24.333416 | C7: 1.9954995 | D7: =B6 -> 0.43213757 | E7: =C6 -> 4.687521 | F7: 0.43213757 | H7: Mode | I7: #N/A | J7: Mode | K7: #N/A | N7: -30 | O7: 0 | R7: -7.5 | S7: 0
A8: 1990 | B8: -20.312388 | C8: 0.47731497 | D8: =B7 -> 24.333416 | E8: =C7 -> 1.9954995 | F8: 24.333416 | H8: Standard Deviation | I8: 14.178956 | J8: Standard Deviation | K8: 2.9110525 | N8: -25 | O8: 1 | R8: -5 | S8: 1
A9: 1991 | B9: 7.6515733 | C9: -1.6101124 | D9: =B8 -> -20.312388 | E9: =C8 -> 0.47731497 | F9: -20.312388 | H9: Sample Variance | I9: 201.0428 | J9: Sample Variance | K9: 8.4742265 | N9: -20 | O9: 1 | R9: -2.5 | S9: 0
A10: 1992 | B10: 8.664776 | C10: 1.0159874 | D10: =B9 -> 7.6515733 | E10: =C9 -> -1.6101124 | F10: 7.6515733 | H10: Kurtosis | I10: 0.99348456 | J10: Kurtosis | K10: 8.2127701 | N10: -15 | O10: 3 | R10: 0 | S10: 3
A11: 1993 | B11: 15.749666 | C11: 3.1912059 | D11: =B10 -> 8.664776 | E11: =C10 -> 1.0159874 | F11: 8.664776 | H11: Skewness | I11: -1.0534341 | J11: Skewness | K11: -2.0901969 | N11: -10 | O11: 2 | R11: 2.5 | S11: 22
A12: 1994 | B12: -13.115204 | C12: 4.5800495 | D12: =B11 -> 15.749666 | E12: =C11 -> 3.1912059 | F12: 15.749666 | H12: Range | I12: 65.435713 | J12: Range | K12: 18.597519 | N12: -5 | O12: 3 | R12: 5 | S12: 13
A13: 1995 | B13: 15.82511 | C13: 3.2078519 | D13: =B12 -> -13.115204 | E13: =C12 -> 4.5800495 | F13: -13.115204 | H13: Minimum | I13: -41.102296 | J13: Minimum | K13: -10.758731 | N13: 0 | O13: 3 | R13: 7.5 | S13: 0
A14: 1996 | B14: 8.1534458 | C14: 2.3266853 | D14: =B13 -> 15.82511 | E14: =C13 -> 3.2078519 | F14: 15.82511 | H14: Maximum | I14: 24.333416 | J14: Maximum | K14: 7.8387873 | N14: 5 | O14: 5 | R14: 10 | S14: 1
A15: 1997 | B15: 19.867676 | C15: 4.507098 | D15: =B14 -> 8.1534458 | E15: =C14 -> 2.3266853 | F15: 8.1534458 | H15: Sum | I15: 83.798788 | J15: Sum | K15: 67.579688 | N15: 10 | O15: 8 | R15: 12.5 | S15: 0
A16: 1998 | B16: 11.761602 | C16: 2.9033293 | D16: =B15 -> 19.867676 | E16: =C15 -> 4.507098 | F16: 19.867676 | H16: Count | I16: 41 | J16: Count | K16: 41 | N16: 15 | O16: 8 | R16: 15 | S16: 0
A17: 1999 | B17: 14.636032 | C17: 2.5685362 | D17: =B16 -> 11.761602 | E17: =C16 -> 2.9033293 | F17: 11.761602 | N17: 20 | O17: 5 | S17: 0
A18: 2000 | B18: -11.954648 | C18: 4.0677158 | D18: =B17 -> 14.636032 | E18: =C17 -> 2.5685362 | F18: 14.636032 | N18: 25 | O18: 1
A19: 2001 | B19: -19.149606 | C19: 1.977909 | D19: =B18 -> -11.954648 | E19: =C18 -> 4.0677158 | F19: -11.954648 | I19: Dy_GB | J19: r_GB(-1) | N19: 30 | O19: 0
A20: 2002 | B20: -29.592098 | C20: 1.2712507 | D20: =B19 -> -19.149606 | E20: =C19 -> 1.977909 | F20: -19.149606 | H20: Dy_GB | I20: 1 | O20: 0
A21: 2003 | B21: 11.38836 | C21: 2.702166 | D21: =B20 -> -29.592098 | E21: =C20 -> 1.2712507 | F21: -29.592098 | H21: r_GB(-1) | I21: 0.22309487 | J21: 1
A22: 2004 | B22: 5.8755837 | C22: 1.7304359 | D22: =B21 -> 11.38836 | E22: =C21 -> 2.702166 | F22: 11.38836
A23: 2005 | B23: 13.36361 | C23: 2.0658142 | D23: =B22 -> 5.8755837 | E23: =C22 -> 1.7304359 | F23: 5.8755837
A24: 2006 | B24: 7.7223781 | C24: 1.4311404 | D24: =B23 -> 13.36361 | E24: =C23 -> 2.0658142 | F24: 13.36361
A25: 2007 | B25: 1.3385196 | C25: 2.1101152 | D25: =B24 -> 7.7223781 | E25: =C24 -> 1.4311404 | F25: 7.7223781
A26: 2008 | B26: -41.102296 | C26: -0.83645651 | D26: =B25 -> 1.3385196 | E26: =C25 -> 2.1101152 | F26: 1.3385196
A27: 2009 | B27: 17.982353 | C27: -5.4523535 | D27: =B26 -> -41.102296 | E27: =C26 -> -0.83645651 | F27: -41.102296
A28: 2010 | B28: 6.1234335 | C28: 1.4514843 | D28: =B27 -> 17.982353 | E28: =C27 -> -5.4523535 | F28: 17.982353
A29: 2011 | B29: -9.5699 | C29: 0.06632689 | D29: =B28 -> 6.1234335 | E29: =C28 -> 1.4514843 | F29: 6.1234335
A30: 2012 | B30: 3.1044442 | C30: 0.80441751 | D30: =B29 -> -9.5699 | E30: =C29 -> 0.06632689 | F30: -9.5699
A31: 2013 | B31: 11.190992 | C31: 1.0343338 | D31: =B30 -> 3.1044442 | E31: =C30 -> 0.80441751 | F31: 3.1044442
A32: 2014 | B32: -4.2000357 | C32: 2.364132 | D32: =B31 -> 11.190992 | E32: =C31 -> 1.0343338 | F32: 11.190992
A33: 2015 | B33: -5.4247086 | C33: 1.3961966 | D33: =B32 -> -4.2000357 | E33: =C32 -> 2.364132 | F33: -4.2000357
... A40: 2022 | B40: -7.0161552 | C40: 4.1001532 | D40: =B39 -> 10.84951 | E40: =C39 -> 7.8387873 | F40: 10.84951
A41: 2023 | B41: -3.0859312 | C41: -1.033698 | D41: =B40 -> -7.0161552 | E41: =C40 -> 4.1001532 | F41: -7.0161552 | H41: Main Regression
A42: 2024 | B42: 2.2594835 | C42: 0.054169325 | D42: =B41 -> -3.0859312 | E42: =C41 -> -1.033698 | F42: -3.0859312 | H42: SUMMARY OUTPUT | K42: X = r_GB(-1)
K43: Y = Dy_GB
H44: Regression Statistics
H45: Multiple R | I45: 0.22309487
H46: R Square | I46: 0.049771321
...

Sheet China
A1: Date | B1: r_CN | C1: Dy_CN | D1: r_CN(-1) | E1: Dy_CN(-1)
A2: 1991 | B2: 79.477341 | C2: 7.5846231 | H2: r_CN | J2: Dy_CN
A3: 1992 | B3: 91.693498 | C3: 12.139762 | D3: =B2 -> 79.477341 | E3: =C2 -> 7.5846231 | N3: r_CN | O3: Frequency | R3: Dy_CN | S3: Frequency
A4: 1993 | B4: -7.9901016 | C4: 11.890975 | D4: =B3 -> 91.693498 | E4: =C3 -> 12.139762 | H4: Mean | I4: 5.9377313 | J4: Mean | K4: 7.8253479 | N4: -120 | O4: {=FREQUENCY(B2:B35,N4:N16)} -> 0 | R4: 0 | S4: {=FREQUENCY(C2:C35,R4:R12)} -> 0
A5: 1994 | B5: -49.48734 | C5: 11.155826 | D5: =B4 -> -7.9901016 | E5: =C4 -> 11.890975 | H5: Standard Error | I5: 6.9909275 | J5: Standard Error | K5: 0.41513002 | N5: -100 | O5: 1 | R5: 2.5 | S5: 1
A6: 1995 | B6: -32.211181 | C6: 9.3790485 | D6: =B5 -> -49.48734 | E6: =C5 -> 11.155826 | H6: Median | I6: 2.1040561 | J6: Median | K6: 7.7212455 | N6: -80 | O6: 0 | R6: 5 | S6: 2
A7: 1996 | B7: 41.8505 | C7: 8.4612377 | D7: =B6 -> -32.211181 | E7: =C6 -> 9.3790485 | H7: Mode | I7: #N/A | J7: Mode | K7: #N/A | N7: -60 | O7: 0 | R7: 7.5 | S7: 13
A8: 1997 | B8: 23.615629 | C8: 7.8578679 | D8: =B7 -> 41.8505 | E8: =C7 -> 8.4612377 | H8: Standard Deviation | I8: 40.763762 | J8: Standard Deviation | K8: 2.4206032 | N8: -40 | O8: 1 | R8: 10 | S8: 12
A9: 1998 | B9: -3.2772651 | C9: 6.6631861 | D9: =B8 -> 23.615629 | E9: =C8 -> 7.8578679 | H9: Sample Variance | I9: 1661.6843 | J9: Sample Variance | K9: 5.8593196 | N9: -20 | O9: 5 | R9: 12.5 | S9: 5
A10: 1999 | B10: 18.943774 | C10: 6.5864401 | D10: =B9 -> -3.2772651 | E10: =C9 -> 6.6631861 | H10: Kurtosis | I10: 1.3330343 | J10: Kurtosis | K10: 0.19644611 | N10: 0 | O10: 9 | R10: 15 | S10: 1
A11: 2000 | B11: 41.343753 | C11: 7.4496712 | D11: =B10 -> 18.943774 | E11: =C10 -> 6.5864401 | H11: Skewness | I11: -0.060880718 | J11: Skewness | K11: 9.4132679e-05 | N11: 20 | O11: 9 | R11: 17.5 | S11: 0
A12: 2001 | B12: -23.808768 | C12: 7.2587857 | D12: =B11 -> 41.343753 | E12: =C11 -> 7.4496712 | H12: Range | I12: 203.73369 | J12: Range | K12: 10.636849 | N12: 40 | O12: 1 | R12: 20 | S12: 0
A13: 2002 | B13: -18.525256 | C13: 8.1708177 | D13: =B12 -> -23.808768 | E13: =C12 -> 7.2587857 | H13: Minimum | I13: -112.04019 | J13: Minimum | K13: 2.075185 | N13: 60 | O13: 4 | S13: 0
A14: 2003 | B14: 8.6458252 | C14: 9.0155474 | D14: =B13 -> -18.525256 | E14: =C13 -> 8.1708177 | H14: Maximum | I14: 91.693498 | J14: Maximum | K14: 12.712034 | N14: 80 | O14: 2
A15: 2004 | B15: -20.548484 | C15: 9.0564751 | D15: =B14 -> 8.6458252 | E15: =C14 -> 9.0155474 | H15: Sum | I15: 201.88286 | J15: Sum | K15: 266.06183 | N15: 100 | O15: 2
A16: 2005 | B16: -10.468738 | C16: 10.259854 | D16: =B15 -> -20.548484 | E16: =C15 -> 9.0564751 | H16: Count | I16: 34 | J16: Count | K16: 34 | N16: 120 | O16: 0
A17: 2006 | B17: 81.830145 | C17: 11.375076 | D17: =B16 -> -10.468738 | E17: =C16 -> 10.259854 | O17: 0
A18: 2007 | B18: 62.813389 | C18: 12.712034 | D18: =B17 -> 81.830145 | E18: =C17 -> 11.375076
A19: 2008 | B19: -112.04019 | C19: 8.7184044 | D19: =B18 -> 62.813389 | E19: =C18 -> 12.712034 | I19: Dy_CN | J19: r_CN(-1)
A20: 2009 | B20: 59.497373 | C20: 8.4891567 | D20: =B19 -> -112.04019 | E20: =C19 -> 8.7184044 | H20: Dy_CN | I20: 1
A21: 2010 | B21: -18.622413 | C21: 9.5886598 | D21: =B20 -> 59.497373 | E21: =C20 -> 8.4891567 | H21: r_CN(-1) | I21: 0.27478033 | J21: 1
A22: 2011 | B22: -29.984657 | C22: 8.4936628 | D22: =B21 -> -18.622413 | E22: =C21 -> 9.5886598
A23: 2012 | B23: 0.50080482 | C23: 6.8844979 | D23: =B22 -> -29.984657 | E23: =C22 -> 8.4936628
A24: 2013 | B24: -9.6089 | C24: 6.8249359 | D24: =B23 -> 0.50080482 | E24: =C23 -> 6.8844979
A25: 2014 | B25: 40.519585 | C25: 6.5662919 | D25: =B24 -> -9.6089 | E25: =C24 -> 6.8249359
A26: 2015 | B26: 7.5596002 | C26: 6.164575 | D26: =B25 -> 40.519585 | E26: =C25 -> 6.5662919
A27: 2016 | B27: -15.1321 | C27: 5.9828325 | D27: =B26 -> 7.5596002 | E27: =C26 -> 6.164575
A28: 2017 | B28: 4.7587434 | C28: 6.0589479 | D28: =B27 -> -15.1321 | E28: =C27 -> 5.9828325
A29: 2018 | B29: -30.29952 | C29: 6.0705676 | D29: =B28 -> 4.7587434 | E29: =C28 -> 6.0589479
A30: 2019 | B30: 17.234376 | C30: 5.5367539 | D30: =B29 -> -30.29952 | E30: =C29 -> 6.0705676
A31: 2020 | B31: 10.566218 | C31: 2.075185 | D31: =B30 -> 17.234376 | E31: =C30 -> 5.5367539
A32: 2021 | B32: 3.7073074 | C32: 8.1333202 | D32: =B31 -> 10.566218 | E32: =C31 -> 2.075185
A33: 2022 | B33: -18.372669 | C33: 3.0991754 | D33: =B32 -> 3.7073074 | E33: =C32 -> 8.1333202
... A35: 2024 | B35: 11.7083 | C35: 4.9805123 | D35: =B34 -> -4.0057111 | E35: =C34 -> 5.3771214
H39: Main Regression
H41: SUMMARY OUTPUT | K41: X = r_CN(-1)
K42: Y = Dy_CN
H43: Regression Statistics
H44: Multiple R | I44: 0.27478033
H45: R Square | I45: 0.075504228
...

Sheet Findings
A3: Table 1: Summary of Descriptive Statistics for China and the UK
A4: Statistics | B4: r_CN | C4: Dy_CN | D4: r_GB | E4: Dy_GB
A5: Mean | B5: =China!I4 -> 5.9377313 | C5: =China!K4 -> 7.8253479 | D5: =UK!I4 -> 2.0438729 | E5: =UK!K4 -> 1.6482851
A6: Standard Error | B6: =China!I5 -> 6.9909275 | C6: =China!K5 -> 0.41513002 | D6: =UK!I5 -> 2.2143809 | E6: =UK!K5 -> 0.45463002
A7: Median | B7: =China!I6 -> 2.1040561 | C7: =China!K6 -> 7.7212455 | D7: =UK!I6 -> 6.1234335 | E7: =UK!K6 -> 1.9954995
A8: Mode | B8: =China!I7 -> #N/A | C8: =China!K7 -> #N/A | D8: =UK!I7 -> #N/A | E8: =UK!K7 -> #N/A
A9: Standard Deviation | B9: =China!I8 -> 40.763762 | C9: =China!K8 -> 2.4206032 | D9: =UK!I8 -> 14.178956 | E9: =UK!K8 -> 2.9110525
A10: Sample Variance | B10: =China!I9 -> 1661.6843 | C10: =China!K9 -> 5.8593196 | D10: =UK!I9 -> 201.0428 | E10: =UK!K9 -> 8.4742265
A11: Kurtosis | B11: =China!I10 -> 1.3330343 | C11: =China!K10 -> 0.19644611 | D11: =UK!I10 -> 0.99348456 | E11: =UK!K10 -> 8.2127701
A12: Skewness | B12: =China!I11 -> -0.060880718 | C12: =China!K11 -> 9.4132679e-05 | D12: =UK!I11 -> -1.0534341 | E12: =UK!K11 -> -2.0901969
A13: Range | B13: =China!I12 -> 203.73369 | C13: =China!K12 -> 10.636849 | D13: =UK!I12 -> 65.435713 | E13: =UK!K12 -> 18.597519
A14: Minimum | B14: =China!I13 -> -112.04019 | C14: =China!K13 -> 2.075185 | D14: =UK!I13 -> -41.102296 | E14: =UK!K13 -> -10.758731
A15: Maximum | B15: =China!I14 -> 91.693498 | C15: =China!K14 -> 12.712034 | D15: =UK!I14 -> 24.333416 | E15: =UK!K14 -> 7.8387873
A16: Sum | B16: =China!I15 -> 201.88286 | C16: =China!K15 -> 266.06183 | D16: =UK!I15 -> 83.798788 | E16: =UK!K15 -> 67.579688
A17: Count | B17: =China!I16 -> 34 | C17: =China!K16 -> 34 | D17: =UK!I16 -> 41 | E17: =UK!K16 -> 41
K19: Figure 1: Distribution of Real Stock Returns - China | W19: Figure 2: Distribution of GDP Growth - China
A20: Table 2: Correlation between Lagged Stock Returns and GDP Growth
C21: China | D21: UK
A22: Correlation | C22: =China!I21 -> 0.27478033 | D22: =UK!I21 -> 0.22309487
A23: Observations (with lag) | C23: =COUNT(China!D2:D35) -> 33 | D23: =COUNT(UK!D2:D42) -> 40
A26: Table 3: Regression of GDP Growth on Lagged Stock Returns - China
B27: Coefficients | C27: Standard Error | D27: t-stat | E27: p-value
A28: Intercept | B28: =China!I57 -> 7.7385962 | C28: =China!J57 -> 0.42211224 | D28: =China!K57 -> 18.333029 | E28: =China!L57 -> 3.4092449e-18
A29: r_CN(-1) | B29: =China!I58 -> 0.016319386 | C29: =China!J58 -> 0.010256278 | D29: =China!K58 -> 1.5911606 | E29: =China!L58 -> 0.12172098
A31: R² | B31: =China!I45 -> 0.075504228
A32: Observations | B32: =China!I48 -> 33
A35: Table 4: Regression of GDP Growth on Lagged Stock Returns - United Kingdom
B36: Coefficients | C36: Standard Error | D36: t-stat | E36: p-value
A37: Intercept | B37: =UK!I58 -> 1.5342797 | C37: =UK!J58 -> 0.46458241 | D37: =UK!K58 -> 3.3024921 | E37: =UK!L58 -> 0.0020935972
A38: r_GB(-1) | B38: =UK!I59 -> 0.045755632 | C38: =UK!J59 -> 0.032432262 | D38: =UK!K59 -> 1.4108061 | E38: =UK!L59 -> 0.16643641
K39: Figure 3: Distribution of Real Stock Returns — United Kingdom | W39: Figure 4: Distribution of GDP Growth — United Kingdom
A40: R² | B40: =UK!I46 -> 0.049771321
A41: Observations | B41: =UK!I49 -> 40
A44: Table 5: Robustness Analysis - Regression with Lagged GDP Growth Included (China)
B45: Coefficients | C45: Standard Error | D45: t-stat | E45: p-value
A46: Intercept | B46: =China!I79 -> 2.805913 | C46: =China!J79 -> 1.1623143 | D46: =China!K79 -> 2.4140742 | E46: =China!L79 -> 0.022085143
A47: r_CN(-1) | B47: =China!I80 -> 0.0097700136 | C47: =China!J80 -> 0.0082397758 | D47: =China!K80 -> 1.1857135 | E47: =China!L80 -> 0.24504236
A48: Dy_CN(-1) | B48: =China!I81 -> 0.62824897 | C48: =China!J81 -> 0.14180851 | D48: =China!K81 -> 4.4302627 | E48: =China!L81 -> 0.00011571607
A50: R² | B50: =China!I67 -> 0.44113595
A51: Observations | B51: =China!I70 -> 33
...

Sheet Temporary
A1: r_CN | B1: r_GB | D1: Dy_CN | E1: Dy_GB
A2: 79.477341 | B2: 15.919408 | D2: 7.5846231 | E2: 2.4776165
A3: 91.693498 | B3: 7.5916845 | D3: 12.139762 | E3: 3.3091661
A4: -7.9901016 | B4: 13.849031 | D4: 11.890975 | E4: 3.702316
A5: -49.48734 | B5: -2.1616529 | D5: 11.155826 | E5: 4.2484411
A6: -32.211181 | B6: 0.43213757 | D6: 9.3790485 | E6: 4.687521
A7: 41.8505 | B7: 24.333416 | D7: 8.4612377 | E7: 1.9954995
A8: 23.615629 | B8: -20.312388 | D8: 7.8578679 | E8: 0.47731497
A9: -3.2772651 | B9: 7.6515733 | D9: 6.6631861 | E9: -1.6101124
A10: 18.943774 | B10: 8.664776 | D10: 6.5864401 | E10: 1.0159874
A11: 41.343753 | B11: 15.749666 | D11: 7.4496712 | E11: 3.1912059
A12: -23.808768 | B12: -13.115204 | D12: 7.2587857 | E12: 4.5800495
A13: -18.525256 | B13: 15.82511 | D13: 8.1708177 | E13: 3.2078519
... A35: 11.7083 | B35: 4.794414 | D35: 4.9805123 | E35: 2.4327175
B36: -15.626191 | E36: 1.0509695
B37: 9.6867446 | E37: 0.73387666
B38: -16.473079 | E38: -10.758731
B39: 10.84951 | E39: 7.8387873
B40: -7.0161552 | E40: 4.1001532
B41: -3.0859312 | E41: -1.033698
B42: 2.2594835 | E42: 0.054169325
